Workbook

Sheet FP
G6: CONSUMO (KWH) | H6: FACTOR DE POTENCIA | I6: CONSUMO (KVAH) | J6: RECARGO/BONIFICACIÓN FACTOR DE POTENCIA | K6: KVArh | M6: RECARGO FP | N6: BONIFICACIÓN FP
B7: =ACOS(H7/100) -> 0.40602005 | C7: =B7*(360/(2*3.1416)) -> 23.263181 | F7: ENERO | G7: ='CON FACTOR DE POTENCIA '!D4 -> 3962 | H7: ='CON FACTOR DE POTENCIA '!E4 -> 91.87 | I7: ='CON FACTOR DE POTENCIA '!F4 -> 4313 | J7: =ROUNDUP(IF(H7<90,M7,N7),2) -> 0.51 | K7: ='CON FACTOR DE POTENCIA '!L4 -> 1704 | M7: =ROUNDUP(IF((3/5)*((90/H7)-1)*100<=120,((3/5)*((90/H7)-1))*(-1)*100,-120),2) -> 1.23 | N7: =((1/4)*((1-(90/H7))))*100 -> 0.50887123
B8: =ACOS(H8/100) -> 0.35311509 | C8: =B8*(360/(2*3.1416)) -> 20.231957 | D8: =G7/I7 -> 0.91861813 | F8: FEBRERO | G8: ='CON FACTOR DE POTENCIA '!D5 -> 3314 | H8: ='CON FACTOR DE POTENCIA '!E5 -> 93.83 | I8: ='CON FACTOR DE POTENCIA '!F5 -> 3532 | J8: =ROUNDUP(IF(H8<90,M8,N8),2) -> 1.03 | K8: ='CON FACTOR DE POTENCIA '!L5 -> 1222 | M8: =ROUNDUP(IF((3/5)*((90/H8)-1)*100<=120,((3/5)*((90/H8)-1))*(-1)*100,-120),2) -> 2.45 | N8: =((1/4)*((1-(90/H8))))*100 -> 1.0204625
B9: =ACOS(H9/100) -> 0.33836095 | C9: =B9*(360/(2*3.1416)) -> 19.386609 | F9: MARZO | G9: ='CON FACTOR DE POTENCIA '!D6 -> 3786 | H9: ='CON FACTOR DE POTENCIA '!E6 -> 94.33 | I9: ='CON FACTOR DE POTENCIA '!F6 -> 4014 | J9: =ROUNDUP(IF(H9<90,M9,N9),2) -> 1.15 | K9: ='CON FACTOR DE POTENCIA '!L6 -> 1333 | M9: =ROUNDUP(IF((3/5)*((90/H9)-1)*100<=120,((3/5)*((90/H9)-1))*(-1)*100,-120),2) -> 2.76 | N9: =((1/4)*((1-(90/H9))))*100 -> 1.1475671
B10: =ACOS(H10/100) -> 0.31401852 | C10: =B10*(360/(2*3.1416)) -> 17.991894 | F10: ABRIL | G10: ='CON FACTOR DE POTENCIA '!D7 -> 4501 | H10: ='CON FACTOR DE POTENCIA '!E7 -> 95.11 | I10: ='CON FACTOR DE POTENCIA '!F7 -> 4733 | J10: =ROUNDUP(IF(H10<90,M10,N10),2) -> 1.35 | K10: ='CON FACTOR DE POTENCIA '!L7 -> 1462 | M10: =ROUNDUP(IF((3/5)*((90/H10)-1)*100<=120,((3/5)*((90/H10)-1))*(-1)*100,-120),2) -> 3.23 | N10: =((1/4)*((1-(90/H10))))*100 -> 1.3431816
B11: =ACOS(H11/100) -> 0.24183565 | C11: =B11*(360/(2*3.1416)) -> 13.85613 | F11: MAYO | G11: ='CON FACTOR DE POTENCIA '!D8 -> 5288 | H11: ='CON FACTOR DE POTENCIA '!E8 -> 97.09 | I11: ='CON FACTOR DE POTENCIA '!F8 -> 5447 | J11: =ROUNDUP(IF(H11<90,M11,N11),2) -> 1.83 | K11: ='CON FACTOR DE POTENCIA '!L8 -> 1305 | M11: =ROUNDUP(IF((3/5)*((90/H11)-1)*100<=120,((3/5)*((90/H11)-1))*(-1)*100,-120),2) -> 4.39 | N11: =((1/4)*((1-(90/H11))))*100 -> 1.8256257
B12: =ACOS(H12/100) -> 0.2776581 | C12: =B12*(360/(2*3.1416)) -> 15.9086 | F12: JUNIO | G12: ='CON FACTOR DE POTENCIA '!D9 -> 5708 | H12: ='CON FACTOR DE POTENCIA '!E9 -> 96.17 | I12: ='CON FACTOR DE POTENCIA '!F9 -> 5936 | J12: =ROUNDUP(IF(H12<90,M12,N12),2) -> 1.61 | K12: ='CON FACTOR DE POTENCIA '!L9 -> 1628 | M12: =ROUNDUP(IF((3/5)*((90/H12)-1)*100<=120,((3/5)*((90/H12)-1))*(-1)*100,-120),2) -> 3.85 | N12: =((1/4)*((1-(90/H12))))*100 -> 1.6039305
B13: =ACOS(H13/100) -> 0.31466537 | C13: =B13*(360/(2*3.1416)) -> 18.028955 | F13: JULIO | G13: ='CON FACTOR DE POTENCIA '!D10 -> 3472 | H13: ='CON FACTOR DE POTENCIA '!E10 -> 95.09 | I13: ='CON FACTOR DE POTENCIA '!F10 -> 3652 | J13: =ROUNDUP(IF(H13<90,M13,N13),2) -> 1.34 | K13: ='CON FACTOR DE POTENCIA '!L10 -> 1131 | M13: =ROUNDUP(IF((3/5)*((90/H13)-1)*100<=120,((3/5)*((90/H13)-1))*(-1)*100,-120),2) -> 3.22 | N13: =((1/4)*((1-(90/H13))))*100 -> 1.3382059
B14: =ACOS(H14/100) -> 0.40220523 | C14: =B14*(360/(2*3.1416)) -> 23.044608 | F14: AGOSTO | G14: ='CON FACTOR DE POTENCIA '!D11 -> 4207 | H14: ='CON FACTOR DE POTENCIA '!E11 -> 92.02 | I14: ='CON FACTOR DE POTENCIA '!F11 -> 4572 | J14: =ROUNDUP(IF(H14<90,M14,N14),2) -> 0.55 | K14: ='CON FACTOR DE POTENCIA '!L11 -> 1790 | M14: =ROUNDUP(IF((3/5)*((90/H14)-1)*100<=120,((3/5)*((90/H14)-1))*(-1)*100,-120),2) -> 1.32 | N14: =((1/4)*((1-(90/H14))))*100 -> 0.54879374
B15: =ACOS(H15/100) -> 1.2661037 | C15: =B15*(360/(2*3.1416)) -> 72.542227 | F15: SEPTIEMBRE | G15: ='CON FACTOR DE POTENCIA '!D12 -> 4760 | H15: ='CON FACTOR DE POTENCIA '!E12 -> 30 | I15: ='CON FACTOR DE POTENCIA '!F12 -> 15867 | J15: =ROUNDUP(IF(H15<90,M15,N15),2) -> -120 | K15: ='CON FACTOR DE POTENCIA '!L12 -> 15137 | M15: =ROUNDUP(IF((3/5)*((90/H15)-1)*100<=120,((3/5)*((90/H15)-1))*(-1)*100,-120),2) -> -120 | N15: =((1/4)*((1-(90/H15))))*100 -> -50
B16: =ACOS(H16/100) -> 0.46549386 | C16: =B16*(360/(2*3.1416)) -> 26.670771 | F16: OCTUBRE | G16: ='CON FACTOR DE POTENCIA '!D13 -> 3989 | H16: ='CON FACTOR DE POTENCIA '!E13 -> 89.36 | I16: ='CON FACTOR DE POTENCIA '!F13 -> 4464 | J16: =ROUNDUP(IF(H16<90,M16,N16),2) -> -0.43 | K16: ='CON FACTOR DE POTENCIA '!L13 -> 2004 | M16: =ROUNDUP(IF((3/5)*((90/H16)-1)*100<=120,((3/5)*((90/H16)-1))*(-1)*100,-120),2) -> -0.43 | N16: =((1/4)*((1-(90/H16))))*100 -> -0.17905103
B17: =ACOS(H17/100) -> 0.44502478 | C17: =B17*(360/(2*3.1416)) -> 25.497982 | F17: NOVIEMBRE | G17: ='CON FACTOR DE POTENCIA '!D14 -> 4366 | H17: ='CON FACTOR DE POTENCIA '!E14 -> 90.26 | I17: ='CON FACTOR DE POTENCIA '!F14 -> 4838 | J17: =ROUNDUP(IF(H17<90,M17,N17),2) -> 0.08 | K17: ='CON FACTOR DE POTENCIA '!L14 -> 2083 | M17: =ROUNDUP(IF((3/5)*((90/H17)-1)*100<=120,((3/5)*((90/H17)-1))*(-1)*100,-120),2) -> 0.18 | N17: =((1/4)*((1-(90/H17))))*100 -> 0.072014181
B18: =ACOS(H18/100) -> 0.42339338 | C18: =B18*(360/(2*3.1416)) -> 24.258597 | F18: DICIEMBRE | G18: ='CON FACTOR DE POTENCIA '!D15 -> 3088 | H18: ='CON FACTOR DE POTENCIA '!E15 -> 91.17 | I18: ='CON FACTOR DE POTENCIA '!F15 -> 3388 | J18: =ROUNDUP(IF(H18<90,M18,N18),2) -> 0.33 | K18: ='CON FACTOR DE POTENCIA '!L15 -> 1392 | M18: =ROUNDUP(IF((3/5)*((90/H18)-1)*100<=120,((3/5)*((90/H18)-1))*(-1)*100,-120),2) -> 0.77 | N18: =((1/4)*((1-(90/H18))))*100 -> 0.32082922
G22: CONSUMO CON FV (KWH) | H22: FACTOR DE POTENCIA CON FV | I22: CONSUMO (KVAH) | J22: RECARGO/BONIFICACIÓN FACTOR DE POTENCIA | K22: KVArh | M22: RECARGO FP | N22: BONIFICACIÓN FP
F23: ENERO | G23: ='CON FACTOR DE POTENCIA '!Q4 -> 1802 | H23: =ROUNDUP(IF(G23>0,(G23/I23)*100,100),2) -> 72.64 | I23: ='CON FACTOR DE POTENCIA '!R4 -> 2481 | J23: =ROUNDUP(IF(H23<90,M23,N23),2) -> -14.34 | K23: =K7 -> 1704 | M23: =ROUNDUP(IF((3/5)*((90/H23)-1)*100<=120,((3/5)*((90/H23)-1))*(-1)*100,-120),2) -> -14.34 | N23: =((1/4)*((1-(90/H23))))*100 -> -5.9746696
D24: =G23/I23 -> 0.72632003 | F24: FEBRERO | G24: ='CON FACTOR DE POTENCIA '!Q5 -> 1117 | H24: =ROUNDUP(IF(G24>0,(G24/I24)*100,100),2) -> 67.46 | I24: ='CON FACTOR DE POTENCIA '!R5 -> 1656 | J24: =ROUNDUP(IF(H24<90,M24,N24),2) -> -20.05 | K24: =K8 -> 1222 | M24: =ROUNDUP(IF((3/5)*((90/H24)-1)*100<=120,((3/5)*((90/H24)-1))*(-1)*100,-120),2) -> -20.05 | N24: =((1/4)*((1-(90/H24))))*100 -> -8.3530981
F25: MARZO | G25: ='CON FACTOR DE POTENCIA '!Q6 -> 1175 | H25: =ROUNDUP(IF(G25>0,(G25/I25)*100,100),2) -> 66.13 | I25: ='CON FACTOR DE POTENCIA '!R6 -> 1777 | J25: =ROUNDUP(IF(H25<90,M25,N25),2) -> -21.66 | K25: =K9 -> 1333 | M25: =ROUNDUP(IF((3/5)*((90/H25)-1)*100<=120,((3/5)*((90/H25)-1))*(-1)*100,-120),2) -> -21.66 | N25: =((1/4)*((1-(90/H25))))*100 -> -9.0238923
F26: ABRIL | G26: ='CON FACTOR DE POTENCIA '!Q7 -> 1970 | H26: =ROUNDUP(IF(G26>0,(G26/I26)*100,100),2) -> 80.28 | I26: ='CON FACTOR DE POTENCIA '!R7 -> 2454 | J26: =ROUNDUP(IF(H26<90,M26,N26),2) -> -7.27 | K26: =K10 -> 1462 | M26: =ROUNDUP(IF((3/5)*((90/H26)-1)*100<=120,((3/5)*((90/H26)-1))*(-1)*100,-120),2) -> -7.27 | N26: =((1/4)*((1-(90/H26))))*100 -> -3.0269058
D27: =SQRT((G23^2)+(K23^2)) -> 2480.0847 | F27: MAYO | G27: ='CON FACTOR DE POTENCIA '!Q8 -> 3004 | H27: =ROUNDUP(IF(G27>0,(G27/I27)*100,100),2) -> 91.7 | I27: ='CON FACTOR DE POTENCIA '!R8 -> 3276 | J27: =ROUNDUP(IF(H27<90,M27,N27),2) -> 0.47 | K27: =K11 -> 1305 | M27: =ROUNDUP(IF((3/5)*((90/H27)-1)*100<=120,((3/5)*((90/H27)-1))*(-1)*100,-120),2) -> 1.12 | N27: =((1/4)*((1-(90/H27))))*100 -> 0.46346783
F28: JUNIO | G28: ='CON FACTOR DE POTENCIA '!Q9 -> 3870 | H28: =ROUNDUP(IF(G28>0,(G28/I28)*100,100),2) -> 92.17 | I28: ='CON FACTOR DE POTENCIA '!R9 -> 4199 | J28: =ROUNDUP(IF(H28<90,M28,N28),2) -> 0.59 | K28: =K12 -> 1628 | M28: =ROUNDUP(IF((3/5)*((90/H28)-1)*100<=120,((3/5)*((90/H28)-1))*(-1)*100,-120),2) -> 1.42 | N28: =((1/4)*((1-(90/H28))))*100 -> 0.58858631
F29: JULIO | G29: ='CON FACTOR DE POTENCIA '!Q10 -> 1639 | H29: =ROUNDUP(IF(G29>0,(G29/I29)*100,100),2) -> 82.28 | I29: ='CON FACTOR DE POTENCIA '!R10 -> 1992 | J29: =ROUNDUP(IF(H29<90,M29,N29),2) -> -5.63 | K29: =K13 -> 1131 | M29: =ROUNDUP(IF((3/5)*((90/H29)-1)*100<=120,((3/5)*((90/H29)-1))*(-1)*100,-120),2) -> -5.63 | N29: =((1/4)*((1-(90/H29))))*100 -> -2.345649
F30: AGOSTO | G30: ='CON FACTOR DE POTENCIA '!Q11 -> 2297 | H30: =ROUNDUP(IF(G30>0,(G30/I30)*100,100),2) -> 78.86 | I30: ='CON FACTOR DE POTENCIA '!R11 -> 2913 | J30: =ROUNDUP(IF(H30<90,M30,N30),2) -> -8.48 | K30: =K14 -> 1790 | M30: =ROUNDUP(IF((3/5)*((90/H30)-1)*100<=120,((3/5)*((90/H30)-1))*(-1)*100,-120),2) -> -8.48 | N30: =((1/4)*((1-(90/H30))))*100 -> -3.5315749
F31: SEPTIEMBRE | G31: ='CON FACTOR DE POTENCIA '!Q12 -> 3020 | H31: =ROUNDUP(IF(G31>0,(G31/I31)*100,100),2) -> 19.57 | I31: ='CON FACTOR DE POTENCIA '!R12 -> 15436 | J31: =ROUNDUP(IF(H31<90,M31,N31),2) -> -120 | K31: =K15 -> 15137 | M31: =ROUNDUP(IF((3/5)*((90/H31)-1)*100<=120,((3/5)*((90/H31)-1))*(-1)*100,-120),2) -> -120 | N31: =((1/4)*((1-(90/H31))))*100 -> -89.971896
F32: OCTUBRE | G32: ='CON FACTOR DE POTENCIA '!Q13 -> 1970 | H32: =ROUNDUP(IF(G32>0,(G32/I32)*100,100),2) -> 70.09 | I32: ='CON FACTOR DE POTENCIA '!R13 -> 2811 | J32: =ROUNDUP(IF(H32<90,M32,N32),2) -> -17.05 | K32: =K16 -> 2004 | M32: =ROUNDUP(IF((3/5)*((90/H32)-1)*100<=120,((3/5)*((90/H32)-1))*(-1)*100,-120),2) -> -17.05 | N32: =((1/4)*((1-(90/H32))))*100 -> -7.1015837
F33: NOVIEMBRE | G33: ='CON FACTOR DE POTENCIA '!Q14 -> 2242 | H33: =ROUNDUP(IF(G33>0,(G33/I33)*100,100),2) -> 73.25 | I33: ='CON FACTOR DE POTENCIA '!R14 -> 3061 | J33: =ROUNDUP(IF(H33<90,M33,N33),2) -> -13.73 | K33: =K17 -> 2083 | M33: =ROUNDUP(IF((3/5)*((90/H33)-1)*100<=120,((3/5)*((90/H33)-1))*(-1)*100,-120),2) -> -13.73 | N33: =((1/4)*((1-(90/H33))))*100 -> -5.7167235
F34: DICIEMBRE | G34: ='CON FACTOR DE POTENCIA '!Q15 -> 921 | H34: =ROUNDUP(IF(G34>0,(G34/I34)*100,100),2) -> 55.15 | I34: ='CON FACTOR DE POTENCIA '!R15 -> 1670 | J34: =ROUNDUP(IF(H34<90,M34,N34),2) -> -37.92 | K34: =K18 -> 1392 | M34: =ROUNDUP(IF((3/5)*((90/H34)-1)*100<=120,((3/5)*((90/H34)-1))*(-1)*100,-120),2) -> -37.92 | N34: =((1/4)*((1-(90/H34))))*100 -> -15.797824

Sheet CON FACTOR DE POTENCIA 
D2: Introducir dato de consumo por mes en kWh | E2: Introducir dato de factor de potencia por mesen (%) | G2: Introducir demanda máxima mensual obtenida del recibo | K2: Factor de carga obtenido en el acuerdo único A/064 2018 | N2: Obtener datos de HSP de plataforma de la NASA
D3: CONSUMO (KWH) | E3: FACTOR DE POTENCIA | F3: CONSUMO (KVAH) | G3: DEMANDA MÁXIMA MENSUAL | H3: DEMANDA MÁXIMA EN PUNTA | I3: DEMANDA ENERGIZADA | J3: RECARGO / BONIFICACIÓN FACTOR DE POTENCIA | K3: FACTOR DE CARGA | L3: KVArh | N3: HSP | O3: DÍAS DEL MES | P3: ENERGÍA GENERADA | Q3: CONSUMO NUEVO (KWH) | R3: CONSUMO NUEVO (KVAH) | S3: FACTOR DE POTENCIA NUEVO | T3: RECARGO POR NUEVO FACTOR DE POTENCIA | U3: DEMANDA MÁXIMA MENSUAL | V3: DEMANDA MÁXIMA EN PUNTA | W3: DEMANDA ENERGIZADA | Z3: Eficiencia ponderada para SFV interconectado | AA3: ESTUDIO FV
C4: ENERO | D4: 3962 | E4: 91.87 | F4: =ROUNDUP(D4/('CON FACTOR DE POTENCIA '!E4/100),0) -> 4313 | G4: 10 | H4: =G4 -> 10 | I4: =ROUNDUP(D4/(24*O4*$K$4),0) -> 10 | J4: =FP!J7 -> 0.51 | K4: 0.55 | L4: =ROUNDUP(SIN(A79)*F4,0) -> 1704 | N4: 5.55 | O4: 31 | P4: =ROUNDDOWN(($AB$5)*$Z$5*N4*O4,0) -> 2160 | Q4: =Q55 -> 1802 | R4: =ROUNDUP(SQRT((Q4^2)+(L4^2)),0) -> 2481 | S4: =FP!H23 -> 72.64 | T4: =FP!J23 -> -14.34 | U4: =G4 -> 10 | V4: =H4 -> 10 | W4: =ROUNDUP(Q4/(24*O4*$K$4),0) -> 5 | Z4: EFICIENCIA | AB4: POTENCIA A INSTALAR (KWP)
C5: FEBRERO | D5: 3314 | E5: 93.83 | F5: =ROUNDUP(D5/('CON FACTOR DE POTENCIA '!E5/100),0) -> 3532 | G5: 9 | H5: =G5 -> 9 | I5: =ROUNDUP(D5/(24*O5*$K$4),0) -> 9 | J5: =FP!J8 -> 1.03 | L5: =ROUNDUP(SIN(A80)*F5,0) -> 1222 | N5: 6.25 | O5: 28 | P5: =ROUNDDOWN(($AB$5)*$Z$5*N5*O5,0) -> 2197 | Q5: =Q56 -> 1117 | R5: =ROUNDUP(SQRT((Q5^2)+(L5^2)),0) -> 1656 | S5: =FP!H24 -> 67.46 | T5: =FP!J24 -> -20.05 | U5: =G5 -> 9 | V5: =H5 -> 9 | W5: =ROUNDUP(Q5/(24*O5*$K$4),0) -> 4 | Z5: 0.75 | AB5: =(Z11*Z14)/1000 -> 16.74
C6: MARZO | D6: 3786 | E6: 94.33 | F6: =ROUNDUP(D6/('CON FACTOR DE POTENCIA '!E6/100),0) -> 4014 | G6: 10 | H6: =G6 -> 10 | I6: =ROUNDUP(D6/(24*O6*$K$4),0) -> 10 | J6: =FP!J9 -> 1.15 | L6: =ROUNDUP(SIN(A81)*F6,0) -> 1333 | N6: 6.71 | O6: 31 | P6: =ROUNDDOWN(($AB$5)*$Z$5*N6*O6,0) -> 2611 | Q6: =Q57 -> 1175 | R6: =ROUNDUP(SQRT((Q6^2)+(L6^2)),0) -> 1777 | S6: =FP!H25 -> 66.13 | T6: =FP!J25 -> -21.66 | U6: =G6 -> 10 | V6: =H6 -> 10 | W6: =ROUNDUP(Q6/(24*O6*$K$4),0) -> 3
C7: ABRIL | D7: 4501 | E7: 95.11 | F7: =ROUNDUP(D7/('CON FACTOR DE POTENCIA '!E7/100),0) -> 4733 | G7: 11 | H7: =G7 -> 11 | I7: =ROUNDUP(D7/(24*O7*$K$4),0) -> 12 | J7: =FP!J10 -> 1.35 | L7: =ROUNDUP(SIN(A82)*F7,0) -> 1462 | N7: 6.72 | O7: 30 | P7: =ROUNDDOWN(($AB$5)*$Z$5*N7*O7,0) -> 2531 | Q7: =Q58 -> 1970 | R7: =ROUNDUP(SQRT((Q7^2)+(L7^2)),0) -> 2454 | S7: =FP!H26 -> 80.28 | T7: =FP!J26 -> -7.27 | U7: =G7 -> 11 | V7: =H7 -> 11 | W7: =ROUNDUP(Q7/(24*O7*$K$4),0) -> 5 | Z7: POTENCIA REQUERIDA (KWP)
C8: MAYO | D8: 5288 | E8: 97.09 | F8: =ROUNDUP(D8/('CON FACTOR DE POTENCIA '!E8/100),0) -> 5447 | G8: 14 | H8: =G8 -> 14 | I8: =ROUNDUP(D8/(24*O8*$K$4),0) -> 13 | J8: =FP!J11 -> 1.83 | L8: =ROUNDUP(SIN(A83)*F8,0) -> 1305 | N8: 5.87 | O8: 31 | P8: =ROUNDDOWN(($AB$5)*$Z$5*N8*O8,0) -> 2284 | Q8: =Q59 -> 3004 | R8: =ROUNDUP(SQRT((Q8^2)+(L8^2)),0) -> 3276 | S8: =FP!H27 -> 91.7 | T8: =FP!J27 -> 0.47 | U8: =G8 -> 14 | V8: =H8 -> 14 | W8: =ROUNDUP(Q8/(24*O8*$K$4),0) -> 8 | Z8: =ROUNDUP(D17/(365*M18*Z5),2) -> 33.51
C9: JUNIO | D9: 5708 | E9: 96.17 | F9: =ROUNDUP(D9/('CON FACTOR DE POTENCIA '!E9/100),0) -> 5936 | G9: 14 | H9: =G9 -> 14 | I9: =ROUNDUP(D9/(24*O9*$K$4),0) -> 15 | J9: =FP!J12 -> 1.61 | L9: =ROUNDUP(SIN(A84)*F9,0) -> 1628 | N9: 4.88 | O9: 30 | P9: =ROUNDDOWN(($AB$5)*$Z$5*N9*O9,0) -> 1838 | Q9: =Q60 -> 3870 | R9: =ROUNDUP(SQRT((Q9^2)+(L9^2)),0) -> 4199 | S9: =FP!H28 -> 92.17 | T9: =FP!J28 -> 0.59 | U9: =G9 -> 14 | V9: =H9 -> 14 | W9: =ROUNDUP(Q9/(24*O9*$K$4),0) -> 10
C10: JULIO | D10: 3472 | E10: 95.09 | F10: =ROUNDUP(D10/('CON FACTOR DE POTENCIA '!E10/100),0) -> 3652 | G10: 9 | H10: =G10 -> 9 | I10: =ROUNDUP(D10/(24*O10*$K$4),0) -> 9 | J10: =FP!J13 -> 1.34 | L10: =ROUNDUP(SIN(A85)*F10,0) -> 1131 | N10: 4.71 | O10: 31 | P10: =ROUNDDOWN(($AB$5)*$Z$5*N10*O10,0) -> 1833 | Q10: =Q61 -> 1639 | R10: =ROUNDUP(SQRT((Q10^2)+(L10^2)),0) -> 1992 | S10: =FP!H29 -> 82.28 | T10: =FP!J29 -> -5.63 | U10: =G10 -> 9 | V10: =H10 -> 9 | W10: =ROUNDUP(Q10/(24*O10*$K$4),0) -> 5 | Z10: Potencia del panel (W) | AA10: Elegir potencia del panel (W)
C11: AGOSTO | D11: 4207 | E11: 92.02 | F11: =ROUNDUP(D11/('CON FACTOR DE POTENCIA '!E11/100),0) -> 4572 | G11: 10 | H11: =G11 -> 10 | I11: =ROUNDUP(D11/(24*O11*$K$4),0) -> 11 | J11: =FP!J14 -> 0.55 | L11: =ROUNDUP(SIN(A86)*F11,0) -> 1790 | N11: 4.91 | O11: 31 | P11: =ROUNDDOWN(($AB$5)*$Z$5*N11*O11,0) -> 1910 | Q11: =Q62 -> 2297 | R11: =ROUNDUP(SQRT((Q11^2)+(L11^2)),0) -> 2913 | S11: =FP!H30 -> 78.86 | T11: =FP!J30 -> -8.48 | U11: =G11 -> 10 | V11: =H11 -> 10 | W11: =ROUNDUP(Q11/(24*O11*$K$4),0) -> 6 | Z11: 620
C12: SEPTIEMBRE | D12: 4760 | E12: 30 | F12: =ROUNDUP(D12/('CON FACTOR DE POTENCIA '!E12/100),0) -> 15867 | G12: 13 | H12: =G12 -> 13 | I12: =ROUNDUP(D12/(24*O12*$K$4),0) -> 13 | J12: =FP!J15 -> -120 | L12: =ROUNDUP(SIN(A87)*F12,0) -> 15137 | N12: 4.62 | O12: 30 | P12: =ROUNDDOWN(($AB$5)*$Z$5*N12*O12,0) -> 1740 | Q12: =Q63 -> 3020 | R12: =ROUNDUP(SQRT((Q12^2)+(L12^2)),0) -> 15436 | S12: =FP!H31 -> 19.57 | T12: =FP!J31 -> -120 | U12: =G12 -> 13 | V12: =H12 -> 13 | W12: =ROUNDUP(Q12/(24*O12*$K$4),0) -> 8
C13: OCTUBRE | D13: 3989 | E13: 89.36 | F13: =ROUNDUP(D13/('CON FACTOR DE POTENCIA '!E13/100),0) -> 4464 | G13: 11 | H13: =G13 -> 11 | I13: =ROUNDUP(D13/(24*O13*$K$4),0) -> 10 | J13: =FP!J16 -> -0.43 | L13: =ROUNDUP(SIN(A88)*F13,0) -> 2004 | N13: 5.19 | O13: 31 | P13: =ROUNDDOWN(($AB$5)*$Z$5*N13*O13,0) -> 2019 | Q13: =Q64 -> 1970 | R13: =ROUNDUP(SQRT((Q13^2)+(L13^2)),0) -> 2811 | S13: =FP!H32 -> 70.09 | T13: =FP!J32 -> -17.05 | U13: =G13 -> 11 | V13: =H13 -> 11 | W13: =ROUNDUP(Q13/(24*O13*$K$4),0) -> 5 | Z13: Número de paneles | AA13: Elegir cantidad de paneles
C14: NOVIEMBRE | D14: 4366 | E14: 90.26 | F14: =ROUNDUP(D14/('CON FACTOR DE POTENCIA '!E14/100),0) -> 4838 | G14: 11 | H14: =G14 -> 11 | I14: =ROUNDUP(D14/(24*O14*$K$4),0) -> 12 | J14: =FP!J17 -> 0.08 | L14: =ROUNDUP(SIN(A89)*F14,0) -> 2083 | N14: 5.64 | O14: 30 | P14: =ROUNDDOWN(($AB$5)*$Z$5*N14*O14,0) -> 2124 | Q14: =Q65 -> 2242 | R14: =ROUNDUP(SQRT((Q14^2)+(L14^2)),0) -> 3061 | S14: =FP!H33 -> 73.25 | T14: =FP!J33 -> -13.73 | U14: =G14 -> 11 | V14: =H14 -> 11 | W14: =ROUNDUP(Q14/(24*O14*$K$4),0) -> 6 | Z14: 27
C15: DICIEMBRE | D15: 3088 | E15: 91.17 | F15: =ROUNDUP(D15/('CON FACTOR DE POTENCIA '!E15/100),0) -> 3388 | G15: 10 | H15: =G15 -> 10 | I15: =ROUNDUP(D15/(24*O15*$K$4),0) -> 8 | J15: =FP!J18 -> 0.33 | L15: =ROUNDUP(SIN(A90)*F15,0) -> 1392 | N15: 5.57 | O15: 31 | P15: =ROUNDDOWN(($AB$5)*$Z$5*N15*O15,0) -> 2167 | Q15: =Q66 -> 921 | R15: =ROUNDUP(SQRT((Q15^2)+(L15^2)),0) -> 1670 | S15: =FP!H34 -> 55.15 | T15: =FP!J34 -> -37.92 | U15: =G15 -> 10 | V15: =H15 -> 10 | W15: =ROUNDUP(Q15/(24*O15*$K$4),0) -> 3
P16: =SUM(P4:P15) -> 25414
C17: TOTAL | D17: =SUM(D4:D15) -> 50441 | F17: =D4/F4 -> 0.91861813 | N17: HSP PROMEDIO ANUAL | O17: TOTAL | Q17: =Q4/R4 -> 0.72632003
M18: =ROUNDDOWN(AVERAGE(N4:N15),1) -> 5.5 | N18: =SUM(P4:P15) -> 25414
T19: MULTIPLICADORES
D20: Actualizar costos a localidad de la instalación | K20: FIJO ($) | L20: ENERGÍA ($/KWH) | M20: DISTRIBUCIÓN ($/KW) | N20: CAPACIDAD ($/KW) | O20: CARGO BAJA TENSIÓN(2%) | P20: CARGO FACTOR DE POTENCIA | Q20: TOTAL | R20: TOTAL + IVA | T20: DISTRIBUCIÓN | U20: CAPACIDAD
D21: FIJO ($) | E21: ENERGIA ($/KWH) | F21: DISTRIBUCIÓN ($/KW) | G21: CAPACIDAD ($/KW) | H21: BAJA TENSION (2%) | J21: ENERO | K21: =D22 -> 474.54 | L21: =D4*E22 -> 5590.382 | M21: =T21*F22 -> 2115.8 | N21: =G22*U21 -> 3134.4 | O21: =(SUM(K21:N21))*0.02 -> 226.30244 | P21: =((J4/100)*(SUM(K21:O21)))*(-1) -> -58.861265 | Q21: =SUM(K21:P21) -> 11482.563 | R21: =Q21*1.16 -> 13319.773 | T21: =IF(I4<=G4,I4,G4) -> 10 | U21: =IF(I4<=H4,I4,H4) -> 10
C22: ENERO | D22: 474.54 | E22: 1.411 | F22: 211.58 | G22: 313.44 | J22: FEBRERO | K22: =D23 -> 474.54 | L22: =D5*E23 -> 4676.054 | M22: =T22*F23 -> 1904.22 | N22: =G23*U22 -> 2820.96 | O22: =(SUM(K22:N22))*0.02 -> 197.51548 | P22: =((J5/100)*(SUM(K22:O22)))*(-1) -> -103.75488 | Q22: =SUM(K22:P22) -> 9969.5346 | R22: =Q22*1.16 -> 11564.66 | T22: =IF(I5<=G5,I5,G5) -> 9 | U22: =IF(I5<=H5,I5,H5) -> 9
C23: FEBRERO | D23: 474.54 | E23: 1.411 | F23: 211.58 | G23: 313.44 | J23: MARZO | K23: =D24 -> 474.54 | L23: =D6*E24 -> 5342.046 | M23: =T23*F24 -> 2115.8 | N23: =G24*U23 -> 3134.4 | O23: =(SUM(K23:N23))*0.02 -> 221.33572 | P23: =((J6/100)*(SUM(K23:O23)))*(-1) -> -129.8134 | Q23: =SUM(K23:P23) -> 11158.308 | R23: =Q23*1.16 -> 12943.638 | T23: =IF(I6<=G6,I6,G6) -> 10 | U23: =IF(I6<=H6,I6,H6) -> 10
C24: MARZO | D24: 474.54 | E24: 1.411 | F24: 211.58 | G24: 313.44 | J24: ABRIL | K24: =D25 -> 474.54 | L24: =D7*E25 -> 6350.911 | M24: =T24*F25 -> 2327.38 | N24: =G25*U24 -> 3447.84 | O24: =(SUM(K24:N24))*0.02 -> 252.01342 | P24: =((J7/100)*(SUM(K24:O24)))*(-1) -> -173.51124 | Q24: =SUM(K24:P24) -> 12679.173 | R24: =Q24*1.16 -> 14707.841 | T24: =IF(I7<=G7,I7,G7) -> 11 | U24: =IF(I7<=H7,I7,H7) -> 11
C25: ABRIL | D25: 474.54 | E25: 1.411 | F25: 211.58 | G25: 313.44 | J25: MAYO | K25: =D26 -> 474.54 | L25: =D8*E26 -> 7461.368 | M25: =T25*F26 -> 2750.54 | N25: =G26*U25 -> 4074.72 | O25: =(SUM(K25:N25))*0.02 -> 295.22336 | P25: =((J8/100)*(SUM(K25:O25)))*(-1) -> -275.53196 | Q25: =SUM(K25:P25) -> 14780.859 | R25: =Q25*1.16 -> 17145.797 | T25: =IF(I8<=G8,I8,G8) -> 13 | U25: =IF(I8<=H8,I8,H8) -> 13
C26: MAYO | D26: 474.54 | E26: 1.411 | F26: 211.58 | G26: 313.44 | J26: JUNIO | K26: =D27 -> 474.54 | L26: =D9*E27 -> 8053.988 | M26: =T26*F27 -> 2962.12 | N26: =G27*U26 -> 4388.16 | O26: =(SUM(K26:N26))*0.02 -> 317.57616 | P26: =((J9/100)*(SUM(K26:O26)))*(-1) -> -260.76178 | Q26: =SUM(K26:P26) -> 15935.622 | R26: =Q26*1.16 -> 18485.322 | T26: =IF(I9<=G9,I9,G9) -> 14 | U26: =IF(I9<=H9,I9,H9) -> 14
C27: JUNIO | D27: 474.54 | E27: 1.411 | F27: 211.58 | G27: 313.44 | J27: JULIO | K27: =D28 -> 474.54 | L27: =D10*E28 -> 4898.992 | M27: =T27*F28 -> 1904.22 | N27: =G28*U27 -> 2820.96 | O27: =(SUM(K27:N27))*0.02 -> 201.97424 | P27: =((J10/100)*(SUM(K27:O27)))*(-1) -> -138.0292 | Q27: =SUM(K27:P27) -> 10162.657 | R27: =Q27*1.16 -> 11788.682 | T27: =IF(I10<=G10,I10,G10) -> 9 | U27: =IF(I10<=H10,I10,H10) -> 9
C28: JULIO | D28: 474.54 | E28: 1.411 | F28: 211.58 | G28: 313.44 | J28: AGOSTO | K28: =D29 -> 474.54 | L28: =D11*E29 -> 5936.077 | M28: =T28*F29 -> 2115.8 | N28: =G29*U28 -> 3134.4 | O28: =(SUM(K28:N28))*0.02 -> 233.21634 | P28: =((J11/100)*(SUM(K28:O28)))*(-1) -> -65.417183 | Q28: =SUM(K28:P28) -> 11828.616 | R28: =Q28*1.16 -> 13721.195 | T28: =IF(I11<=G11,I11,G11) -> 10 | U28: =IF(I11<=H11,I11,H11) -> 10
C29: AGOSTO | D29: 474.54 | E29: 1.411 | F29: 211.58 | G29: 313.44 | J29: SEPTIEMBRE | K29: =D30 -> 474.54 | L29: =D12*E30 -> 6716.36 | M29: =T29*F30 -> 2750.54 | N29: =G30*U29 -> 4074.72 | O29: =(SUM(K29:N29))*0.02 -> 280.3232 | P29: =((J12/100)*(SUM(K29:O29)))*(-1) -> 17155.78 | Q29: =SUM(K29:P29) -> 31452.263 | R29: =Q29*1.16 -> 36484.625 | T29: =IF(I12<=G12,I12,G12) -> 13 | U29: =IF(I12<=H12,I12,H12) -> 13
C30: SEPTIEMBRE | D30: 474.54 | E30: 1.411 | F30: 211.58 | G30: 313.44 | J30: OCTUBRE | K30: =D31 -> 474.54 | L30: =D13*E31 -> 5628.479 | M30: =T30*F31 -> 2115.8 | N30: =G31*U30 -> 3134.4 | O30: =(SUM(K30:N30))*0.02 -> 227.06438 | P30: =((J13/100)*(SUM(K30:O30)))*(-1) -> 49.795219 | Q30: =SUM(K30:P30) -> 11630.079 | R30: =Q30*1.16 -> 13490.891 | T30: =IF(I13<=G13,I13,G13) -> 10 | U30: =IF(I13<=H13,I13,H13) -> 10
C31: OCTUBRE | D31: 474.54 | E31: 1.411 | F31: 211.58 | G31: 313.44 | J31: NOVIEMBRE | K31: =D32 -> 474.54 | L31: =D14*E32 -> 6160.426 | M31: =T31*F32 -> 2327.38 | N31: =G32*U31 -> 3447.84 | O31: =(SUM(K31:N31))*0.02 -> 248.20372 | P31: =((J14/100)*(SUM(K31:O31)))*(-1) -> -10.126712 | Q31: =SUM(K31:P31) -> 12648.263 | R31: =Q31*1.16 -> 14671.985 | T31: =IF(I14<=G14,I14,G14) -> 11 | U31: =IF(I14<=H14,I14,H14) -> 11
C32: NOVIEMBRE | D32: 474.54 | E32: 1.411 | F32: 211.58 | G32: 313.44 | J32: DICIEMBRE | K32: =D33 -> 474.54 | L32: =D15*E33 -> 4357.168 | M32: =T32*F33 -> 1692.64 | N32: =G33*U32 -> 2507.52 | O32: =(SUM(K32:N32))*0.02 -> 180.63736 | P32: =((J15/100)*(SUM(K32:O32)))*(-1) -> -30.401268 | Q32: =SUM(K32:P32) -> 9182.1041 | R32: =Q32*1.16 -> 10651.241 | T32: =IF(I15<=G15,I15,G15) -> 8 | U32: =IF(I15<=H15,I15,H15) -> 8
C33: DICIEMBRE | D33: 474.54 | E33: 1.411 | F33: 211.58 | G33: 313.44 | Q33: =SUM(Q21:Q32) -> 162910.04 | R33: =Q33*1.16 -> 188975.65
L35: CON FOTOVOLTAICO
K36: FIJO ($) | L36: ENERGÍA ($/KWH) | M36: DISTRIBUCIÓN ($/KW) | N36: CAPACIDAD ($/KW) | O36: CARGO POR BAJA TENSIÓN (2%) | P36: CARGO FACTOR DE POTENCIA | Q36: TOTAL | R36: TOTAL + IVA | T36: MULTIPLICADORES
J37: ENERO | K37: =K21 -> 474.54 | L37: =Q4*E22 -> 2542.622 | M37: =T38*F22 -> 1057.9 | N37: =G22*U38 -> 1567.2 | O37: =(SUM(K37:N37))*0.02 -> 112.84524 | P37: =((T4/100)*SUM(K37:O37))*(-1) -> 825.28238 | Q37: =SUM(K37:P37) -> 6580.3896 | R37: =Q37*1.16 -> 7633.252 | T37: DISTRIBUCIÓN | U37: CAPACIDAD
J38: FEBRERO | K38: =K22 -> 474.54 | L38: =Q5*E23 -> 1576.087 | M38: =T39*F23 -> 846.32 | N38: =G23*U39 -> 1253.76 | O38: =(SUM(K38:N38))*0.02 -> 83.01414 | P38: =((T5/100)*SUM(K38:O38))*(-1) -> 848.86109 | Q38: =SUM(K38:P38) -> 5082.5822 | R38: =Q38*1.16 -> 5895.7954 | T38: =IF(W4<=U4,W4,U4) -> 5 | U38: =IF(W4<=V4,W4,V4) -> 5
J39: MARZO | K39: =K23 -> 474.54 | L39: =Q6*E24 -> 1657.925 | M39: =T40*F24 -> 634.74 | N39: =G24*U40 -> 940.32 | O39: =(SUM(K39:N39))*0.02 -> 74.1505 | P39: =((T6/100)*SUM(K39:O39))*(-1) -> 819.11091 | Q39: =SUM(K39:P39) -> 4600.7864 | R39: =Q39*1.16 -> 5336.9122 | T39: =IF(W5<=U5,W5,U5) -> 4 | U39: =IF(W5<=V5,W5,V5) -> 4
J40: ABRIL | K40: =K24 -> 474.54 | L40: =Q7*E25 -> 2779.67 | M40: =T41*F25 -> 1057.9 | N40: =G25*U41 -> 1567.2 | O40: =(SUM(K40:N40))*0.02 -> 117.5862 | P40: =((T7/100)*SUM(K40:O40))*(-1) -> 435.97435 | Q40: =SUM(K40:P40) -> 6432.8706 | R40: =Q40*1.16 -> 7462.1298 | T40: =IF(W6<=U6,W6,U6) -> 3 | U40: =IF(W6<=V6,W6,V6) -> 3
J41: MAYO | K41: =K25 -> 474.54 | L41: =Q8*E26 -> 4238.644 | M41: =T42*F26 -> 1692.64 | N41: =G26*U42 -> 2507.52 | O41: =(SUM(K41:N41))*0.02 -> 178.26688 | P41: =((T8/100)*SUM(K41:O41))*(-1) -> -42.730571 | Q41: =SUM(K41:P41) -> 9048.8803 | R41: =Q41*1.16 -> 10496.701 | T41: =IF(W7<=U7,W7,U7) -> 5 | U41: =IF(W7<=V7,W7,V7) -> 5
J42: JUNIO | K42: =K26 -> 474.54 | L42: =Q9*E27 -> 5460.57 | M42: =T43*F27 -> 2115.8 | N42: =G27*U43 -> 3134.4 | O42: =(SUM(K42:N42))*0.02 -> 223.7062 | P42: =((T9/100)*SUM(K42:O42))*(-1) -> -67.313196 | Q42: =SUM(K42:P42) -> 11341.703 | R42: =Q42*1.16 -> 13156.375 | T42: =IF(W8<=U8,W8,U8) -> 8 | U42: =IF(W8<=V8,W8,V8) -> 8
...

Sheet tabla general
F5: Mes | G5: Consumo histórico (kWh) | H5: Energía generada por el sistema (kWh) | I5: Pago histórico ($) | J5: Pago nuevo ($) | K5: Ahorro por periodo ($)
F6: Enero | G6: ='CON FACTOR DE POTENCIA '!D4 -> 3962 | H6: 1355 | I6: ='CON FACTOR DE POTENCIA '!R21 -> 13319.773 | J6: ='CON FACTOR DE POTENCIA '!R37 -> 7633.252 | K6: =I6-J6 -> 5686.5213
F7: Febrero | G7: ='CON FACTOR DE POTENCIA '!D5 -> 3314 | H7: 1471 | I7: ='CON FACTOR DE POTENCIA '!R22 -> 11564.66 | J7: ='CON FACTOR DE POTENCIA '!R38 -> 5895.7954 | K7: =I7-J7 -> 5668.8647
F8: Marzo | G8: ='CON FACTOR DE POTENCIA '!D6 -> 3786 | H8: 1907 | I8: ='CON FACTOR DE POTENCIA '!R23 -> 12943.638 | J8: ='CON FACTOR DE POTENCIA '!R39 -> 5336.9122 | K8: =I8-J8 -> 7606.7254
F9: Abril | G9: ='CON FACTOR DE POTENCIA '!D7 -> 4501 | H9: 1965 | I9: ='CON FACTOR DE POTENCIA '!R24 -> 14707.841 | J9: ='CON FACTOR DE POTENCIA '!R40 -> 7462.1298 | K9: =I9-J9 -> 7245.711
F10: Mayo | G10: ='CON FACTOR DE POTENCIA '!D8 -> 5288 | H10: 2095 | I10: ='CON FACTOR DE POTENCIA '!R25 -> 17145.797 | J10: ='CON FACTOR DE POTENCIA '!R41 -> 10496.701 | K10: =I10-J10 -> 6649.0957
F11: Junio | G11: ='CON FACTOR DE POTENCIA '!D9 -> 5708 | H11: 1873 | I11: ='CON FACTOR DE POTENCIA '!R26 -> 18485.322 | J11: ='CON FACTOR DE POTENCIA '!R42 -> 13156.375 | K11: =I11-J11 -> 5328.9465
F12: Julio | G12: ='CON FACTOR DE POTENCIA '!D10 -> 3472 | H12: 1727 | I12: ='CON FACTOR DE POTENCIA '!R27 -> 11788.682 | J12: ='CON FACTOR DE POTENCIA '!R43 -> 6764.3304 | K12: =I12-J12 -> 5024.3517
F13: Agosto | G13: ='CON FACTOR DE POTENCIA '!D11 -> 4207 | H13: 1642 | I13: ='CON FACTOR DE POTENCIA '!R28 -> 13721.195 | J13: ='CON FACTOR DE POTENCIA '!R44 -> 8812.4034 | K13: =I13-J13 -> 4908.7914
F14: Septiembre | G14: ='CON FACTOR DE POTENCIA '!D12 -> 4760 | H14: 1527 | I14: ='CON FACTOR DE POTENCIA '!R29 -> 36484.625 | J14: ='CON FACTOR DE POTENCIA '!R45 -> 23260.557 | K14: =I14-J14 -> 13224.068
F15: Octubre | G15: ='CON FACTOR DE POTENCIA '!D13 -> 3989 | H15: 1671 | I15: ='CON FACTOR DE POTENCIA '!R30 -> 13490.891 | J15: ='CON FACTOR DE POTENCIA '!R46 -> 8142.4657 | K15: =I15-J15 -> 5348.4255
F16: Noviembre | G16: ='CON FACTOR DE POTENCIA '!D14 -> 4366 | H16: 1412 | I16: ='CON FACTOR DE POTENCIA '!R31 -> 14671.985 | J16: ='CON FACTOR DE POTENCIA '!R47 -> 9134.4592 | K16: =I16-J16 -> 5537.5259
F17: Diciembre | G17: ='CON FACTOR DE POTENCIA '!D15 -> 3088 | H17: 1316 | I17: ='CON FACTOR DE POTENCIA '!R32 -> 10651.241 | J17: ='CON FACTOR DE POTENCIA '!R48 -> 5465.3445 | K17: =I17-J17 -> 5185.8962
F18: Ahorro anual | K18: =SUM(K6:K17) -> 77414.923
F19: Retorno de inversión | J19: ='COTIZACIÓN '!E11/'tabla general'!K18 -> 3.7599355 | K19: años

Sheet COTIZACIÓN 
C5: Descripción | D5: Total | H5: COSTO SFV | J5: TIPO DE CAMBIO
C6: Tamaño del sistema | E6: ='CON FACTOR DE POTENCIA '!AB5*1000 -> 16740 | F6: W | H6: =E11 -> 291075.12 | J6: 19.32
C7: Precio dólar/ watt (18.945) | E7: =H9 -> 0.9
C8: Precio (USD) | D8: USD | E8: =(E6*E7)/1.16 -> 12987.931 | H8: Costo USD / Watt
C9: Subtotal (MXN) | E9: =E8*J6 -> 250926.83 | H9: 0.9
C10: IVA (MXN) | E10: =E9*0.16 -> 40148.292
C11: TOTAL (MXN) | E11: =SUM(E9:E10) -> 291075.12

Sheet ROI
G3: AÑO | H3: AHORRO | I3: AHORRO ACUMULADO | K3: INFLACIÓN ANUAL (5%)
G4: 1 | H4: ='tabla general'!K18 -> 77414.923 | I4: =H4 -> 77414.923 | K4: 5
G5: 2 | H5: =H4*(1+($K$4/100)) -> 81285.67 | I5: =I4+H5 -> 158700.59
G6: 3 | H6: =H5*(1+($K$4/100)) -> 85349.953 | I6: =I5+H6 -> 244050.55
G7: 4 | H7: =H6*(1+($K$4/100)) -> 89617.451 | I7: =I6+H7 -> 333668
G8: 5 | H8: =H7*(1+($K$4/100)) -> 94098.323 | I8: =I7+H8 -> 427766.32
G9: 6 | H9: =H8*(1+($K$4/100)) -> 98803.239 | I9: =I8+H9 -> 526569.56
G10: 7 | H10: =H9*(1+($K$4/100)) -> 103743.4 | I10: =I9+H10 -> 630312.96
G11: 8 | H11: =H10*(1+($K$4/100)) -> 108930.57 | I11: =I10+H11 -> 739243.53
G12: 9 | H12: =H11*(1+($K$4/100)) -> 114377.1 | I12: =I11+H12 -> 853620.63
G13: 10 | H13: =H12*(1+($K$4/100)) -> 120095.95 | I13: =I12+H13 -> 973716.59
G14: 11 | H14: =H13*(1+($K$4/100)) -> 126100.75 | I14: =I13+H14 -> 1099817.3
G15: 12 | H15: =H14*(1+($K$4/100)) -> 132405.79 | I15: =I14+H15 -> 1232223.1
G16: 13 | H16: =H15*(1+($K$4/100)) -> 139026.08 | I16: =I15+H16 -> 1371249.2
... G28: 25 | H28: =H27*(1+($K$4/100)) -> 249670.86 | I28: =I27+H28 -> 3694789.7
