Workbook

Sheet TARIFA
D13: 1 | F13: INVIERNO | J13: VERANO
E14: BASICO | F14: INTERMEDIO | G14: EXCEDENTE | I14: BÁSICO | J14: INTERMEDIO BAJO | K14: INTERMEDIO ALTO | L14: EXCEDENTE
E15: 75 | F15: 65 | I15: 75 | J15: 65 | K15: 0
D17: 1 A | F17: INVIERNO | J17: VERANO
D18: 2 | E18: BASICO | F18: INTERMEDIO | G18: EXCEDENTE | I18: BÁSICO | J18: INTERMEDIO BAJO | K18: INTERMEDIO ALTO | L18: EXCEDENTE
E19: 75 | F19: 75 | I19: 100 | J19: 50 | K19: 100
D21: 1 B | F21: INVIERNO | J21: VERANO
D22: 3 | E22: BASICO | F22: INTERMEDIO | G22: EXCEDENTE | I22: BÁSICO | J22: INTERMEDIO BAJO | K22: INTERMEDIO ALTO | L22: EXCEDENTE
E23: 75 | F23: 100 | I23: 125 | J23: 100 | K23: 0
D25: 1 C | F25: INVIERNO | J25: VERANO
D26: 4 | E26: BASICO | F26: INTERMEDIO | G26: EXCEDENTE | I26: BÁSICO | J26: INTERMEDIO BAJO | K26: INTERMEDIO ALTO | L26: EXCEDENTE
E27: 75 | F27: 100 | I27: 150 | J27: 150 | K27: 150
D29: 1 D | F29: INVIERNO | J29: VERANO
D30: 5 | E30: BASICO | F30: INTERMEDIO | G30: EXCEDENTE | I30: BÁSICO | J30: INTERMEDIO BAJO | K30: INTERMEDIO ALTO | L30: EXCEDENTE
E31: 75 | F31: 125 | I31: 175 | J31: 225 | K31: 200
D33: 1 E | F33: INVIERNO | J33: VERANO
D34: 6 | E34: BASICO | F34: INTERMEDIO | G34: EXCEDENTE | I34: BÁSICO | J34: INTERMEDIO BAJO | K34: INTERMEDIO ALTO | L34: EXCEDENTE
E35: 75 | F35: 125 | I35: 300 | J35: 450 | K35: 150
D37: 1 F | F37: INVIERNO | J37: VERANO
D38: 7 | E38: BASICO | F38: INTERMEDIO | G38: EXCEDENTE | I38: BÁSICO | J38: INTERMEDIO BAJO | K38: INTERMEDIO ALTO | L38: EXCEDENTE
E39: 75 | F39: 125 | I39: 300 | J39: 900 | K39: 1300
B41: Nota: elegir tarifa | C41: TARIFA APLICABLE
B42: aplicable al sitio de la instalación | C42: 5 | F42: INVIERNO | J42: VERANO
E43: BASICO | F43: INTERMEDIO | G43: EXCEDENTE | I43: BÁSICO | J43: INTERMEDIO BAJO | K43: INTERMEDIO ALTO | L43: EXCEDENTE
E44: =_xlfn.IFS(C42=D13,E15,C42=D18,E19,C42=D22,E23,C42=D26,E27,C42=D30,E31,C42=D34,E35,C42=D38,E39) -> 75 | F44: =_xlfn.IFS(C42=D13,F15,C42=D18,F19,C42=D22,F23,C42=D26,F27,C42=D30,F31,C42=D34,F35,C42=D38,F39) -> 125 | I44: =_xlfn.IFS($C$42=$D$13,I15,$C$42=$D$18,I19,$C$42=$D$22,I23,$C$42=$D$26,I27,$C$42=$D$30,I31,$C$42=$D$34,I35,$C$42=$D$38,I39) -> 175 | J44: =_xlfn.IFS($C$42=$D$13,J15,$C$42=$D$18,J19,$C$42=$D$22,J23,$C$42=$D$26,J27,$C$42=$D$30,J31,$C$42=$D$34,J35,$C$42=$D$38,J39) -> 225 | K44: =_xlfn.IFS($C$42=$D$13,K15,$C$42=$D$18,K19,$C$42=$D$22,K23,$C$42=$D$26,K27,$C$42=$D$30,K31,$C$42=$D$34,K35,$C$42=$D$38,K39) -> 200
D47: Tarifa | E47: # indicador | F47: Nota: elegir tarifa en función de su número
D48: 1 | E48: 1
D49: 1A | E49: 2 | F49: Por ejemplo:
D50: 1B | E50: 3 | F50: Para tarifa 1F, el número indicador es el 7
D51: 1C | E51: 4
D52: 1D | E52: 5
D53: 1E | E53: 6
D54: 1F | E54: 7

Sheet Desglose energía
D2: Nota: determinar consumos por mes* | H2: Desglose de energía | M2: Cobros por kWh
D3: Mes | E3: Consumo (kWh) | G3: Básico | H3: Intermedio | I3: Intermedio alto | J3: Excedente | L3: Básico | M3: Intermedio | N3: Intermedio alto | O3: Excedente
D4: ENERO | E4: 324 | G4: =IF(E4>=TARIFA!$E$44,TARIFA!$E$44,E4) -> 75 | H4: =_xlfn.IFS(E4<=G4,0, E4>=TARIFA!$E$44+TARIFA!$F$44,TARIFA!$F$44, E4<TARIFA!$E$44+TARIFA!$F$44, E4-TARIFA!$E$44) -> 125 | J4: =IF(E4<=TARIFA!$E$44+TARIFA!$F$44,0,E4-(TARIFA!$E$44+TARIFA!$F$44)) -> 124 | L4: 1.063 | M4: 1.29 | O4: 3.777
D5: FEBRERO | E5: 180 | G5: =IF(E5>=TARIFA!$E$44,TARIFA!$E$44,E5) -> 75 | H5: =_xlfn.IFS(E5<=G5,0, E5>=TARIFA!$E$44+TARIFA!$F$44,TARIFA!$F$44, E5<TARIFA!$E$44+TARIFA!$F$44, E5-TARIFA!$E$44) -> 105 | J5: =IF(E5<=TARIFA!$E$44+TARIFA!$F$44,0,E5-(TARIFA!$E$44+TARIFA!$F$44)) -> 0 | L5: 1.063 | M5: 1.29 | O5: 3.777
D6: MARZO | E6: 188 | G6: =IF(E6>=TARIFA!$E$44,TARIFA!$E$44,E6) -> 75 | H6: =_xlfn.IFS(E6<=G6,0, E6>=TARIFA!$E$44+TARIFA!$F$44,TARIFA!$F$44, E6<TARIFA!$E$44+TARIFA!$F$44, E6-TARIFA!$E$44) -> 113 | J6: =IF(E6<=TARIFA!$E$44+TARIFA!$F$44,0,E6-(TARIFA!$E$44+TARIFA!$F$44)) -> 0 | L6: 1.063 | M6: 1.29 | O6: 3.777
D7: ABRIL | E7: 250 | G7: =IF(E7>=TARIFA!$E$44,TARIFA!$E$44,E7) -> 75 | H7: =_xlfn.IFS(E7<=G7,0, E7>=TARIFA!$E$44+TARIFA!$F$44,TARIFA!$F$44, E7<TARIFA!$E$44+TARIFA!$F$44, E7-TARIFA!$E$44) -> 125 | J7: =IF(E7<=TARIFA!$E$44+TARIFA!$F$44,0,E7-(TARIFA!$E$44+TARIFA!$F$44)) -> 50 | L7: 1.063 | M7: 1.29 | O7: 3.777
A8: =IF(E8<=TARIFA!$I$44+TARIFA!$J$44+TARIFA!$K$44,1,2) -> 1 | D8: MAYO | E8: 512 | G8: =IF(E8>=TARIFA!$I$44,TARIFA!$I$44,E8) -> 175 | H8: =_xlfn.IFS(E8<=TARIFA!$I$44,0, E8>=TARIFA!$I$44+TARIFA!$J$44,TARIFA!$J$44, E8<TARIFA!$I$44+TARIFA!$J$44, E8-TARIFA!$I$44) -> 225 | I8: {=_xlfn.IFS(E8<=TARIFA!$I$44+TARIFA!$J$44,0,A8=1,E8-TARIFA!$I$44-TARIFA!$J$44,A8=2,TARIFA!$K$44)} -> 112 | J8: =IF(E8<=TARIFA!$I$44+TARIFA!$J$44+TARIFA!$K$44,0,E8-(TARIFA!$I$44+TARIFA!$J$44+TARIFA!$K$44)) -> 0 | L8: 0.965 | M8: 1.119 | N8: 1.44 | O8: 3.847
A9: =IF(E9<=TARIFA!$I$44+TARIFA!$J$44+TARIFA!$K$44,1,2) -> 2 | D9: JUNIO | E9: 1350 | G9: =IF(E9>=TARIFA!$I$44,TARIFA!$I$44,E9) -> 175 | H9: =_xlfn.IFS(E9<=TARIFA!$I$44,0, E9>=TARIFA!$I$44+TARIFA!$J$44,TARIFA!$J$44, E9<TARIFA!$I$44+TARIFA!$J$44, E9-TARIFA!$I$44) -> 225 | I9: =_xlfn.IFS(E9<=TARIFA!$I$44+TARIFA!$J$44,0,A9=1,E9-TARIFA!$I$44-TARIFA!$J$44,A9=2,TARIFA!$K$44) -> 200 | J9: =IF(E9<=TARIFA!$I$44+TARIFA!$J$44+TARIFA!$K$44,0,E9-(TARIFA!$I$44+TARIFA!$J$44+TARIFA!$K$44)) -> 750 | L9: 0.965 | M9: 1.119 | N9: 1.44 | O9: 3.847
A10: =IF(E10<=TARIFA!$I$44+TARIFA!$J$44+TARIFA!$K$44,1,2) -> 2 | D10: JULIO | E10: 1430 | G10: =IF(E10>=TARIFA!$I$44,TARIFA!$I$44,E10) -> 175 | H10: =_xlfn.IFS(E10<=TARIFA!$I$44,0, E10>=TARIFA!$I$44+TARIFA!$J$44,TARIFA!$J$44, E10<TARIFA!$I$44+TARIFA!$J$44, E10-TARIFA!$I$44) -> 225 | I10: =_xlfn.IFS(E10<=TARIFA!$I$44+TARIFA!$J$44,0,A10=1,E10-TARIFA!$I$44-TARIFA!$J$44,A10=2,TARIFA!$K$44) -> 200 | J10: =IF(E10<=TARIFA!$I$44+TARIFA!$J$44+TARIFA!$K$44,0,E10-(TARIFA!$I$44+TARIFA!$J$44+TARIFA!$K$44)) -> 830 | L10: 0.965 | M10: 1.119 | N10: 1.44 | O10: 3.847
A11: =IF(E11<=TARIFA!$I$44+TARIFA!$J$44+TARIFA!$K$44,1,2) -> 2 | D11: AGOSTO | E11: 1730 | G11: =IF(E11>=TARIFA!$I$44,TARIFA!$I$44,E11) -> 175 | H11: =_xlfn.IFS(E11<=TARIFA!$I$44,0, E11>=TARIFA!$I$44+TARIFA!$J$44,TARIFA!$J$44, E11<TARIFA!$I$44+TARIFA!$J$44, E11-TARIFA!$I$44) -> 225 | I11: =_xlfn.IFS(E11<=TARIFA!$I$44+TARIFA!$J$44,0,A11=1,E11-TARIFA!$I$44-TARIFA!$J$44,A11=2,TARIFA!$K$44) -> 200 | J11: =IF(E11<=TARIFA!$I$44+TARIFA!$J$44+TARIFA!$K$44,0,E11-(TARIFA!$I$44+TARIFA!$J$44+TARIFA!$K$44)) -> 1130 | L11: 0.965 | M11: 1.119 | N11: 1.44 | O11: 3.847
A12: =IF(E12<=TARIFA!$I$44+TARIFA!$J$44+TARIFA!$K$44,1,2) -> 2 | D12: SEPTIEMBRE | E12: 1511 | G12: =IF(E12>=TARIFA!$I$44,TARIFA!$I$44,E12) -> 175 | H12: =_xlfn.IFS(E12<=TARIFA!$I$44,0, E12>=TARIFA!$I$44+TARIFA!$J$44,TARIFA!$J$44, E12<TARIFA!$I$44+TARIFA!$J$44, E12-TARIFA!$I$44) -> 225 | I12: =_xlfn.IFS(E12<=TARIFA!$I$44+TARIFA!$J$44,0,A12=1,E12-TARIFA!$I$44-TARIFA!$J$44,A12=2,TARIFA!$K$44) -> 200 | J12: =IF(E12<=TARIFA!$I$44+TARIFA!$J$44+TARIFA!$K$44,0,E12-(TARIFA!$I$44+TARIFA!$J$44+TARIFA!$K$44)) -> 911 | L12: 0.965 | M12: 1.119 | N12: 1.44 | O12: 3.847
A13: =IF(E13<=TARIFA!$I$44+TARIFA!$J$44+TARIFA!$K$44,1,2) -> 2 | D13: OCTUBRE | E13: 1500 | G13: =IF(E13>=TARIFA!$I$44,TARIFA!$I$44,E13) -> 175 | H13: =_xlfn.IFS(E13<=TARIFA!$I$44,0, E13>=TARIFA!$I$44+TARIFA!$J$44,TARIFA!$J$44, E13<TARIFA!$I$44+TARIFA!$J$44, E13-TARIFA!$I$44) -> 225 | I13: =_xlfn.IFS(E13<=TARIFA!$I$44+TARIFA!$J$44,0,A13=1,E13-TARIFA!$I$44-TARIFA!$J$44,A13=2,TARIFA!$K$44) -> 200 | J13: =IF(E13<=TARIFA!$I$44+TARIFA!$J$44+TARIFA!$K$44,0,E13-(TARIFA!$I$44+TARIFA!$J$44+TARIFA!$K$44)) -> 900 | L13: 0.965 | M13: 1.119 | N13: 1.44 | O13: 3.847
D14: NOVIEMBRE | E14: 1432 | G14: =IF(E14>=TARIFA!$E$44,TARIFA!$E$44,E14) -> 75 | H14: =_xlfn.IFS(E14<=G14,0, E14>=TARIFA!$E$44+TARIFA!$F$44,TARIFA!$F$44,E14<TARIFA!$E$44+TARIFA!$F$44, E14-TARIFA!$E$44) -> 125 | J14: =IF(E14<=TARIFA!$E$44+TARIFA!$F$44,0,E14-(TARIFA!$E$44+TARIFA!$F$44)) -> 1232 | L14: 1.063 | M14: 1.29 | O14: 3.777
D15: DICIEMBRE | E15: 570 | G15: =IF(E15>=TARIFA!$E$44,TARIFA!$E$44,E15) -> 75 | H15: =_xlfn.IFS(E15<=G15,0, E15>=TARIFA!$E$44+TARIFA!$F$44,TARIFA!$F$44,E15<TARIFA!$E$44+TARIFA!$F$44, E15-TARIFA!$E$44) -> 125 | J15: =IF(E15<=TARIFA!$E$44+TARIFA!$F$44,0,E15-(TARIFA!$E$44+TARIFA!$F$44)) -> 370 | L15: 1.063 | M15: 1.29 | O15: 3.777
E16: =SUM(E4:E15) -> 10977 | J16: =SUM(J4:J15) -> 6297
D19: Mes | E19: $ básico | F19: $ intermedio | G19: $ Intermedio alto | H19: $ excedente | I19: Total | J19: Total + IVA
D20: ENERO | E20: =G4*L4 -> 79.725 | F20: =H4*M4 -> 161.25 | G20: =I4*N4 -> 0 | H20: =J4*O4 -> 468.348 | I20: =SUM(E20:H20) -> 709.323 | J20: =(SUM(E20:H20))*1.16 -> 822.81468
D21: FEBRERO | E21: =G5*L5 -> 79.725 | F21: =H5*M5 -> 135.45 | G21: =I5*N5 -> 0 | H21: =J5*O5 -> 0 | I21: =SUM(E21:H21) -> 215.175 | J21: =(SUM(E21:H21))*1.16 -> 249.603
D22: MARZO | E22: =G6*L6 -> 79.725 | F22: =H6*M6 -> 145.77 | G22: =I6*N6 -> 0 | H22: =J6*O6 -> 0 | I22: =SUM(E22:H22) -> 225.495 | J22: =(SUM(E22:H22))*1.16 -> 261.5742
D23: ABRIL | E23: =G7*L7 -> 79.725 | F23: =H7*M7 -> 161.25 | G23: =I7*N7 -> 0 | H23: =J7*O7 -> 188.85 | I23: =SUM(E23:H23) -> 429.825 | J23: =(SUM(E23:H23))*1.16 -> 498.597
D24: MAYO | E24: =G8*L8 -> 168.875 | F24: =H8*M8 -> 251.775 | G24: =I8*N8 -> 161.28 | H24: =J8*O8 -> 0 | I24: =SUM(E24:H24) -> 581.93 | J24: =(SUM(E24:H24))*1.16 -> 675.0388
D25: JUNIO | E25: =G9*L9 -> 168.875 | F25: =H9*M9 -> 251.775 | G25: =I9*N9 -> 288 | H25: =J9*O9 -> 2885.25 | I25: =SUM(E25:H25) -> 3593.9 | J25: =(SUM(E25:H25))*1.16 -> 4168.924
D26: JULIO | E26: =G10*L10 -> 168.875 | F26: =H10*M10 -> 251.775 | G26: =I10*N10 -> 288 | H26: =J10*O10 -> 3193.01 | I26: =SUM(E26:H26) -> 3901.66 | J26: =(SUM(E26:H26))*1.16 -> 4525.9256
D27: AGOSTO | E27: =G11*L11 -> 168.875 | F27: =H11*M11 -> 251.775 | G27: =I11*N11 -> 288 | H27: =J11*O11 -> 4347.11 | I27: =SUM(E27:H27) -> 5055.76 | J27: =(SUM(E27:H27))*1.16 -> 5864.6816
D28: SEPTIEMBRE | E28: =G12*L12 -> 168.875 | F28: =H12*M12 -> 251.775 | G28: =I12*N12 -> 288 | H28: =J12*O12 -> 3504.617 | I28: =SUM(E28:H28) -> 4213.267 | J28: =(SUM(E28:H28))*1.16 -> 4887.3897
D29: OCTUBRE | E29: =G13*L13 -> 168.875 | F29: =H13*M13 -> 251.775 | G29: =I13*N13 -> 288 | H29: =J13*O13 -> 3462.3 | I29: =SUM(E29:H29) -> 4170.95 | J29: =(SUM(E29:H29))*1.16 -> 4838.302
D30: NOVIEMBRE | E30: =G14*L14 -> 79.725 | F30: =H14*M14 -> 161.25 | G30: =I14*N14 -> 0 | H30: =J14*O14 -> 4653.264 | I30: =SUM(E30:H30) -> 4894.239 | J30: =(SUM(E30:H30))*1.16 -> 5677.3172
D31: DICIEMBRE | E31: =G15*L15 -> 79.725 | F31: =H15*M15 -> 161.25 | G31: =I15*N15 -> 0 | H31: =J15*O15 -> 1397.49 | I31: =SUM(E31:H31) -> 1638.465 | J31: =(SUM(E31:H31))*1.16 -> 1900.6194
J32: =SUM(J20:J31) -> 34370.787

Sheet Con FV
I4: Desglose de energía | M4: Potencia a instalar (kW) | O4: Eficiencia | P4: Nota: eficiencia dependerá de condiciones de instalación*
C5: Mes | D5: Consumo antiguo | E5: Consumo nuevo(kWh) | H5: Básico | I5: Intermedio | J5: Intermedio alto | K5: Excedente | M5: =M11*M8*0.001 -> 2.48 | O5: 0.75 | P5: Se podrá tomar como estándar 75% con una orientación e inclinación adecuadas
C6: ENERO | D6: ='Desglose energía'!E4 -> 324 | E6: =F59 -> 0 | G6: ENERO | H6: =IF(E6>=TARIFA!$E$44,TARIFA!$E$44,E6) -> 0 | I6: =_xlfn.IFS(E6<=H6,0, E6>=TARIFA!$E$44+TARIFA!$F$44,TARIFA!$F$44, E6<TARIFA!$E$44+TARIFA!$F$44, E6-TARIFA!$E$44) -> 0 | K6: =IF(E6<=TARIFA!$E$44+TARIFA!$F$44,0,E6-(TARIFA!$E$44+TARIFA!$F$44)) -> 0
C7: FEBRERO | D7: ='Desglose energía'!E5 -> 180 | E7: =F60 -> 0 | G7: FEBRERO | H7: =IF(E7>=TARIFA!$E$44,TARIFA!$E$44,E7) -> 0 | I7: =_xlfn.IFS(E7<=H7,0, E7>=TARIFA!$E$44+TARIFA!$F$44,TARIFA!$F$44, E7<TARIFA!$E$44+TARIFA!$F$44, E7-TARIFA!$E$44) -> 0 | K7: =IF(E7<=TARIFA!$E$44+TARIFA!$F$44,0,E7-(TARIFA!$E$44+TARIFA!$F$44)) -> 0 | M7: Potencia de panel (Wp) | N7: Nota: elegir potencia de panel a instalar* | R7: Potencia necesaria (kW)
A8: =IF(E10<=TARIFA!$I$44+TARIFA!$J$44+TARIFA!$K$44,1,2) -> 1 | C8: MARZO | D8: ='Desglose energía'!E6 -> 188 | E8: =F61 -> 0 | G8: MARZO | H8: =IF(E8>=TARIFA!$E$44,TARIFA!$E$44,E8) -> 0 | I8: =_xlfn.IFS(E8<=H8,0, E8>=TARIFA!$E$44+TARIFA!$F$44,TARIFA!$F$44, E8<TARIFA!$E$44+TARIFA!$F$44, E8-TARIFA!$E$44) -> 0 | K8: =IF(E8<=TARIFA!$E$44+TARIFA!$F$44,0,E8-(TARIFA!$E$44+TARIFA!$F$44)) -> 0 | M8: 620 | R8: =ROUNDUP((D19/(365*E36*O5)),1) -> 6.5
A9: =IF(E11<=TARIFA!$I$44+TARIFA!$J$44+TARIFA!$K$44,1,2) -> 1 | C9: ABRIL | D9: ='Desglose energía'!E7 -> 250 | E9: =F62 -> 0 | G9: ABRIL | H9: =IF(E9>=TARIFA!$E$44,TARIFA!$E$44,E9) -> 0 | I9: =_xlfn.IFS(E9<=H9,0, E9>=TARIFA!$E$44+TARIFA!$F$44,TARIFA!$F$44, E9<TARIFA!$E$44+TARIFA!$F$44, E9-TARIFA!$E$44) -> 0 | K9: =IF(E9<=TARIFA!$E$44+TARIFA!$F$44,0,E9-(TARIFA!$E$44+TARIFA!$F$44)) -> 0
A10: =IF(E12<=TARIFA!$I$44+TARIFA!$J$44+TARIFA!$K$44,1,2) -> 2 | C10: MAYO | D10: ='Desglose energía'!E8 -> 512 | E10: =F63 -> 0 | G10: MAYO | H10: =IF(E10>=TARIFA!$I$44,TARIFA!$I$44,E10) -> 0 | I10: =_xlfn.IFS(E10<=TARIFA!$I$44,0, E10>=TARIFA!$I$44+TARIFA!$J$44,TARIFA!$J$44, E10<TARIFA!$I$44+TARIFA!$J$44, E10-TARIFA!$I$44) -> 0 | J10: {=_xlfn.IFS(E10<=TARIFA!$I$44+TARIFA!$J$44,0,A8=1,E10-TARIFA!$I$44-TARIFA!$J$44,A8=2,TARIFA!$K$44)} -> 0 | K10: =IF(E10<=TARIFA!$I$44+TARIFA!$J$44+TARIFA!$K$44,0,E10-(TARIFA!$I$44+TARIFA!$J$44+TARIFA!$K$44)) -> 0 | M10: Cantidad de paneles a instalar | N10: Nota: elegir cantidad de paneles a instalar*
A11: =IF(E13<=TARIFA!$I$44+TARIFA!$J$44+TARIFA!$K$44,1,2) -> 2 | C11: JUNIO | D11: ='Desglose energía'!E9 -> 1350 | E11: =F64 -> 561 | G11: JUNIO | H11: =IF(E11>=TARIFA!$I$44,TARIFA!$I$44,E11) -> 175 | I11: =_xlfn.IFS(E11<=TARIFA!$I$44,0, E11>=TARIFA!$I$44+TARIFA!$J$44,TARIFA!$J$44, E11<TARIFA!$I$44+TARIFA!$J$44, E11-TARIFA!$I$44) -> 225 | J11: {=_xlfn.IFS(E11<=TARIFA!$I$44+TARIFA!$J$44,0,A9=1,E11-TARIFA!$I$44-TARIFA!$J$44,A9=2,TARIFA!$K$44)} -> 161 | K11: =IF(E11<=TARIFA!$I$44+TARIFA!$J$44+TARIFA!$K$44,0,E11-(TARIFA!$I$44+TARIFA!$J$44+TARIFA!$K$44)) -> 0 | M11: 4
A12: =IF(E14<=TARIFA!$I$44+TARIFA!$J$44+TARIFA!$K$44,1,2) -> 2 | C12: JULIO | D12: ='Desglose energía'!E10 -> 1430 | E12: =F65 -> 1107 | G12: JULIO | H12: =IF(E12>=TARIFA!$I$44,TARIFA!$I$44,E12) -> 175 | I12: =_xlfn.IFS(E12<=TARIFA!$I$44,0, E12>=TARIFA!$I$44+TARIFA!$J$44,TARIFA!$J$44, E12<TARIFA!$I$44+TARIFA!$J$44, E12-TARIFA!$I$44) -> 225 | J12: {=_xlfn.IFS(E12<=TARIFA!$I$44+TARIFA!$J$44,0,A10=1,E12-TARIFA!$I$44-TARIFA!$J$44,A10=2,TARIFA!$K$44)} -> 200 | K12: =IF(E12<=TARIFA!$I$44+TARIFA!$J$44+TARIFA!$K$44,0,E12-(TARIFA!$I$44+TARIFA!$J$44+TARIFA!$K$44)) -> 507
A13: =IF(E15<=TARIFA!$I$44+TARIFA!$J$44+TARIFA!$K$44,1,2) -> 2 | C13: AGOSTO | D13: ='Desglose energía'!E11 -> 1730 | E13: =F66 -> 1402 | G13: AGOSTO | H13: =IF(E13>=TARIFA!$I$44,TARIFA!$I$44,E13) -> 175 | I13: =_xlfn.IFS(E13<=TARIFA!$I$44,0, E13>=TARIFA!$I$44+TARIFA!$J$44,TARIFA!$J$44, E13<TARIFA!$I$44+TARIFA!$J$44, E13-TARIFA!$I$44) -> 225 | J13: {=_xlfn.IFS(E13<=TARIFA!$I$44+TARIFA!$J$44,0,A11=1,E13-TARIFA!$I$44-TARIFA!$J$44,A11=2,TARIFA!$K$44)} -> 200 | K13: =IF(E13<=TARIFA!$I$44+TARIFA!$J$44+TARIFA!$K$44,0,E13-(TARIFA!$I$44+TARIFA!$J$44+TARIFA!$K$44)) -> 802
C14: SEPTIEMBRE | D14: ='Desglose energía'!E12 -> 1511 | E14: =F67 -> 1206 | G14: SEPTIEMBRE | H14: =IF(E14>=TARIFA!$I$44,TARIFA!$I$44,E14) -> 175 | I14: =_xlfn.IFS(E14<=TARIFA!$I$44,0, E14>=TARIFA!$I$44+TARIFA!$J$44,TARIFA!$J$44, E14<TARIFA!$I$44+TARIFA!$J$44, E14-TARIFA!$I$44) -> 225 | J14: {=_xlfn.IFS(E14<=TARIFA!$I$44+TARIFA!$J$44,0,A12=1,E14-TARIFA!$I$44-TARIFA!$J$44,A12=2,TARIFA!$K$44)} -> 200 | K14: =IF(E14<=TARIFA!$I$44+TARIFA!$J$44+TARIFA!$K$44,0,E14-(TARIFA!$I$44+TARIFA!$J$44+TARIFA!$K$44)) -> 606
C15: OCTUBRE | D15: ='Desglose energía'!E13 -> 1500 | E15: =F68 -> 1145 | G15: OCTUBRE | H15: =IF(E15>=TARIFA!$I$44,TARIFA!$I$44,E15) -> 175 | I15: =_xlfn.IFS(E15<=TARIFA!$I$44,0, E15>=TARIFA!$I$44+TARIFA!$J$44,TARIFA!$J$44, E15<TARIFA!$I$44+TARIFA!$J$44, E15-TARIFA!$I$44) -> 225 | J15: {=_xlfn.IFS(E15<=TARIFA!$I$44+TARIFA!$J$44,0,A13=1,E15-TARIFA!$I$44-TARIFA!$J$44,A13=2,TARIFA!$K$44)} -> 200 | K15: =IF(E15<=TARIFA!$I$44+TARIFA!$J$44+TARIFA!$K$44,0,E15-(TARIFA!$I$44+TARIFA!$J$44+TARIFA!$K$44)) -> 545
C16: NOVIEMBRE | D16: ='Desglose energía'!E14 -> 1432 | E16: =F69 -> 1088 | G16: NOVIEMBRE | H16: =IF(E16>=TARIFA!$E$44,TARIFA!$E$44,E16) -> 75 | I16: =_xlfn.IFS(E16<=H16,0, E16>=TARIFA!$E$44+TARIFA!$F$44,TARIFA!$F$44,E16<TARIFA!$E$44+TARIFA!$F$44, E16-TARIFA!$E$44) -> 125 | K16: =IF(E16<=TARIFA!$E$44+TARIFA!$F$44,0,E16-(TARIFA!$E$44+TARIFA!$F$44)) -> 888
C17: DICIEMBRE | D17: ='Desglose energía'!E15 -> 570 | E17: =F70 -> 245 | G17: DICIEMBRE | H17: =IF(E17>=TARIFA!$E$44,TARIFA!$E$44,E17) -> 75 | I17: =_xlfn.IFS(E17<=H17,0, E17>=TARIFA!$E$44+TARIFA!$F$44,TARIFA!$F$44,E17<TARIFA!$E$44+TARIFA!$F$44, E17-TARIFA!$E$44) -> 125 | K17: =IF(E17<=TARIFA!$E$44+TARIFA!$F$44,0,E17-(TARIFA!$E$44+TARIFA!$F$44)) -> 45
D18: Total | E18: Total
D19: =SUM(D6:D17) -> 10977 | E19: =SUM(E6:E17) -> 6754
C21: Nota: las HSP se deberán cambiar acorde al sitio de la instalación*
C22: Generación | I22: Cobros por kWh
C23: Mes | D23: Días | E23: HSP (23°) | F23: Generación | H23: Básico | I23: Intermedio | J23: Intermedio alto | K23: Excedente
C24: ENERO | D24: 31 | E24: 5.74 | F24: =ROUNDDOWN($M$5*$O$5*E24*D24,0) -> 330 | H24: ='Desglose energía'!L4 -> 1.063 | I24: ='Desglose energía'!M4 -> 1.29 | J24: ='Desglose energía'!N4 -> 0 | K24: ='Desglose energía'!O4 -> 3.777
C25: FEBRERO | D25: 28 | E25: 6.57 | F25: =ROUNDDOWN($M$5*$O$5*E25*D25,0) -> 342 | H25: ='Desglose energía'!L5 -> 1.063 | I25: ='Desglose energía'!M5 -> 1.29 | J25: ='Desglose energía'!N5 -> 0 | K25: ='Desglose energía'!O5 -> 3.777
C26: MARZO | D26: 31 | E26: 7.3 | F26: =ROUNDDOWN($M$5*$O$5*E26*D26,0) -> 420 | H26: ='Desglose energía'!L6 -> 1.063 | I26: ='Desglose energía'!M6 -> 1.29 | J26: ='Desglose energía'!N6 -> 0 | K26: ='Desglose energía'!O6 -> 3.777
C27: ABRIL | D27: 30 | E27: 7.34 | F27: =ROUNDDOWN($M$5*$O$5*E27*D27,0) -> 409 | H27: ='Desglose energía'!L7 -> 1.063 | I27: ='Desglose energía'!M7 -> 1.29 | J27: ='Desglose energía'!N7 -> 0 | K27: ='Desglose energía'!O7 -> 3.777
C28: MAYO | D28: 31 | E28: 7.01 | F28: =ROUNDDOWN($M$5*$O$5*E28*D28,0) -> 404 | H28: ='Desglose energía'!L8 -> 0.965 | I28: ='Desglose energía'!M8 -> 1.119 | J28: ='Desglose energía'!N8 -> 1.44 | K28: ='Desglose energía'!O8 -> 3.847
C29: JUNIO | D29: 30 | E29: 6.06 | F29: =ROUNDDOWN($M$5*$O$5*E29*D29,0) -> 338 | H29: ='Desglose energía'!L9 -> 0.965 | I29: ='Desglose energía'!M9 -> 1.119 | J29: ='Desglose energía'!N9 -> 1.44 | K29: ='Desglose energía'!O9 -> 3.847
C30: JULIO | D30: 31 | E30: 5.61 | F30: =ROUNDDOWN($M$5*$O$5*E30*D30,0) -> 323 | H30: ='Desglose energía'!L10 -> 0.965 | I30: ='Desglose energía'!M10 -> 1.119 | J30: ='Desglose energía'!N10 -> 1.44 | K30: ='Desglose energía'!O10 -> 3.847
C31: AGOSTO | D31: 31 | E31: 5.7 | F31: =ROUNDDOWN($M$5*$O$5*E31*D31,0) -> 328 | H31: ='Desglose energía'!L11 -> 0.965 | I31: ='Desglose energía'!M11 -> 1.119 | J31: ='Desglose energía'!N11 -> 1.44 | K31: ='Desglose energía'!O11 -> 3.847
C32: SEPTIEMBRE | D32: 30 | E32: 5.47 | F32: =ROUNDDOWN($M$5*$O$5*E32*D32,0) -> 305 | H32: ='Desglose energía'!L12 -> 0.965 | I32: ='Desglose energía'!M12 -> 1.119 | J32: ='Desglose energía'!N12 -> 1.44 | K32: ='Desglose energía'!O12 -> 3.847
C33: OCTUBRE | D33: 31 | E33: 6.16 | F33: =ROUNDDOWN($M$5*$O$5*E33*D33,0) -> 355 | H33: ='Desglose energía'!L13 -> 0.965 | I33: ='Desglose energía'!M13 -> 1.119 | J33: ='Desglose energía'!N13 -> 1.44 | K33: ='Desglose energía'!O13 -> 3.847
C34: NOVIEMBRE | D34: 30 | E34: 6.17 | F34: =ROUNDDOWN($M$5*$O$5*E34*D34,0) -> 344 | H34: ='Desglose energía'!L14 -> 1.063 | I34: ='Desglose energía'!M14 -> 1.29 | J34: ='Desglose energía'!N14 -> 0 | K34: ='Desglose energía'!O14 -> 3.777
C35: DICIEMBRE | D35: 31 | E35: 5.64 | F35: =ROUNDDOWN($M$5*$O$5*E35*D35,0) -> 325 | H35: ='Desglose energía'!L15 -> 1.063 | I35: ='Desglose energía'!M15 -> 1.29 | J35: ='Desglose energía'!N15 -> 0 | K35: ='Desglose energía'!O15 -> 3.777
E36: =(ROUNDDOWN(AVERAGE(E24:E35),2)) -> 6.23 | F36: =SUM(F24:F35) -> 4223
C39: Mes | D39: $ básico | E39: $ intermedio | F39: $ Intermedio alto | G39: $ excedente | I39: Total | J39: Total + IVA
C40: ENERO | D40: =H6*H24 -> 0 | E40: =I6*I24 -> 0 | F40: =J6*J24 -> 0 | G40: =K6*K24 -> 0 | I40: =IF(SUM(D40:G40)<=0,0,SUM(D40:G40)) -> 0 | J40: =ROUNDUP(I40*1.16,2) -> 0
C41: FEBRERO | D41: =H7*H25 -> 0 | E41: =I7*I25 -> 0 | F41: =J7*J25 -> 0 | G41: =K7*K25 -> 0 | I41: =IF(SUM(D41:G41)<=0,0,SUM(D41:G41)) -> 0 | J41: =ROUNDUP(I41*1.16,2) -> 0
C42: MARZO | D42: =H8*H26 -> 0 | E42: =I8*I26 -> 0 | F42: =J8*J26 -> 0 | G42: =K8*K26 -> 0 | I42: =IF(SUM(D42:G42)<=0,0,SUM(D42:G42)) -> 0 | J42: =ROUNDUP(I42*1.16,2) -> 0
C43: ABRIL | D43: =H9*H27 -> 0 | E43: =I9*I27 -> 0 | F43: =J9*J27 -> 0 | G43: =K9*K27 -> 0 | I43: =IF(SUM(D43:G43)<=0,0,SUM(D43:G43)) -> 0 | J43: =ROUNDUP(I43*1.16,2) -> 0
C44: MAYO | D44: =H10*H28 -> 0 | E44: =I10*I28 -> 0 | F44: =J10*J28 -> 0 | G44: =K10*K28 -> 0 | I44: =IF(SUM(D44:G44)<=0,0,SUM(D44:G44)) -> 0 | J44: =ROUNDUP(I44*1.16,2) -> 0
C45: JUNIO | D45: =H11*H29 -> 168.875 | E45: =I11*I29 -> 251.775 | F45: =J11*J29 -> 231.84 | G45: =K11*K29 -> 0 | I45: =IF(SUM(D45:G45)<=0,0,SUM(D45:G45)) -> 652.49 | J45: =ROUNDUP(I45*1.16,2) -> 756.89
C46: JULIO | D46: =H12*H30 -> 168.875 | E46: =I12*I30 -> 251.775 | F46: =J12*J30 -> 288 | G46: =K12*K30 -> 1950.429 | I46: =IF(SUM(D46:G46)<=0,0,SUM(D46:G46)) -> 2659.079 | J46: =ROUNDUP(I46*1.16,2) -> 3084.54
...

Sheet GRÁFICA GENERAL
E8: Mes | F8: Consumo histórico (kWh) | G8: Energía generada por el sistema (kWh) | H8: Pago histórico ($) | I8: Pago nuevo ($) | J8: Ahorro por periodo ($)
E9: Enero | F9: ='Con FV'!D6 -> 324 | G9: ='Con FV'!F24 -> 330 | H9: ='Desglose energía'!J20 -> 822.81468 | I9: ='Con FV'!J40 -> 0 | J9: =H9-I9 -> 822.81468
E10: Febrero | F10: ='Con FV'!D7 -> 180 | G10: ='Con FV'!F25 -> 342 | H10: ='Desglose energía'!J21 -> 249.603 | I10: ='Con FV'!J41 -> 0 | J10: =H10-I10 -> 249.603
E11: Marzo | F11: ='Con FV'!D8 -> 188 | G11: ='Con FV'!F26 -> 420 | H11: ='Desglose energía'!J22 -> 261.5742 | I11: ='Con FV'!J42 -> 0 | J11: =H11-I11 -> 261.5742
E12: Abril | F12: ='Con FV'!D9 -> 250 | G12: ='Con FV'!F27 -> 409 | H12: ='Desglose energía'!J23 -> 498.597 | I12: ='Con FV'!J43 -> 0 | J12: =H12-I12 -> 498.597
E13: Mayo | F13: ='Con FV'!D10 -> 512 | G13: ='Con FV'!F28 -> 404 | H13: ='Desglose energía'!J24 -> 675.0388 | I13: ='Con FV'!J44 -> 0 | J13: =H13-I13 -> 675.0388
E14: Junio | F14: ='Con FV'!D11 -> 1350 | G14: ='Con FV'!F29 -> 338 | H14: ='Desglose energía'!J25 -> 4168.924 | I14: ='Con FV'!J45 -> 756.89 | J14: =H14-I14 -> 3412.034
E15: Julio | F15: ='Con FV'!D12 -> 1430 | G15: ='Con FV'!F30 -> 323 | H15: ='Desglose energía'!J26 -> 4525.9256 | I15: ='Con FV'!J46 -> 3084.54 | J15: =H15-I15 -> 1441.3856
E16: Agosto | F16: ='Con FV'!D13 -> 1730 | G16: ='Con FV'!F31 -> 328 | H16: ='Desglose energía'!J27 -> 5864.6816 | I16: ='Con FV'!J47 -> 4400.98 | J16: =H16-I16 -> 1463.7016
E17: Septiembre | F17: ='Con FV'!D14 -> 1511 | G17: ='Con FV'!F32 -> 305 | H17: ='Desglose energía'!J28 -> 4887.3897 | I17: ='Con FV'!J48 -> 3526.33 | J17: =H17-I17 -> 1361.0597
E18: Octubre | F18: ='Con FV'!D15 -> 1500 | G18: ='Con FV'!F33 -> 355 | H18: ='Desglose energía'!J29 -> 4838.302 | I18: ='Con FV'!J49 -> 3254.11 | J18: =H18-I18 -> 1584.192
E19: Noviembre | F19: ='Con FV'!D16 -> 1432 | G19: ='Con FV'!F34 -> 344 | H19: ='Desglose energía'!J30 -> 5677.3172 | I19: ='Con FV'!J50 -> 4170.15 | J19: =H19-I19 -> 1507.1672
E20: Diciembre | F20: ='Con FV'!D17 -> 570 | G20: ='Con FV'!F35 -> 325 | H20: ='Desglose energía'!J31 -> 1900.6194 | I20: ='Con FV'!J51 -> 476.7 | J20: =H20-I20 -> 1423.9194
E21: Ahorro anual | J21: =SUM(J9:J20) -> 14701.087
E22: Retorno de inversión estimado (ROI) | I22: =COSTOS!G24 -> 2.68 | J22: años

Sheet COSTOS
B5: Nota: Rango de precio (usd /watt) | D5: COSTO POR WATT (USD /WATT) | F5: POTENCIA A INSTALAR (KWP) | H5: 0.75-1.1
B6: 0.85-1.1 | D6: 0.85 | F6: ='Con FV'!M5 -> 2.48
B8: Variar de acuerdo a tipo de cambio de | D8: TIPO DE CAMBIO | F8: COSTO TOTAL (MXN)
B9: DOF al día de cotización | D9: 18.6267 | F9: =(F6*1000)*D6*D9 -> 39265.084 | H9: =F9*0.25 -> 9816.2709
F10: =F9*0.25 -> 9816.2709
F11: =(F10/1.16*0.98) -> 8293.0565
C14: Descripción | F14: Total
C15: tamaño del sistema | F15: =F6*1000 -> 2480 | G15: W
C16: T.C. | F16: =D9 -> 18.6267
C17: Precio dólar/ watt | F17: =ROUNDUP(D6/1.16,5) -> 0.73276
C18: Subtotal (MXN) | F18: =F15*F17*D9 -> 33849.274
C19: IVA (MXN) | F19: =F18*0.16 -> 5415.8838
C20: TOTAL (MXN) | F20: =F18+F19 -> 39265.158
G23: ROI ESTIMADO
G24: =ROUNDUP(F20/'GRÁFICA GENERAL'!J21,2) -> 2.68

Sheet AHORRO ACUMULADO
F4: AÑO | G4: AHORRO ANUAL | I4: AHORRO ACUMULADO | K4: INFLACIÓN (%)
F5: 1 | G5: ='GRÁFICA GENERAL'!J21 -> 14701.087 | I5: =G5 -> 14701.087 | K5: 5
F6: 2 | G6: =G5*((100+$K$5)/100) -> 15436.142 | I6: =I5+G6 -> 30137.229
F7: 3 | G7: =G6*((100+$K$5)/100) -> 16207.949 | I7: =I6+G7 -> 46345.178
F8: 4 | G8: =G7*((100+$K$5)/100) -> 17018.346 | I8: =I7+G8 -> 63363.524
F9: 5 | G9: =G8*((100+$K$5)/100) -> 17869.263 | I9: =I8+G9 -> 81232.787
F10: 6 | G10: =G9*((100+$K$5)/100) -> 18762.727 | I10: =I9+G10 -> 99995.514
F11: 7 | G11: =G10*((100+$K$5)/100) -> 19700.863 | I11: =I10+G11 -> 119696.38
F12: 8 | G12: =G11*((100+$K$5)/100) -> 20685.906 | I12: =I11+G12 -> 140382.28
F13: 9 | G13: =G12*((100+$K$5)/100) -> 21720.201 | I13: =I12+G13 -> 162102.48
F14: 10 | G14: =G13*((100+$K$5)/100) -> 22806.211 | I14: =I13+G14 -> 184908.7
F15: 11 | G15: =G14*((100+$K$5)/100) -> 23946.522 | I15: =I14+G15 -> 208855.22
F16: 12 | G16: =G15*((100+$K$5)/100) -> 25143.848 | I16: =I15+G16 -> 233999.07
F17: 13 | G17: =G16*((100+$K$5)/100) -> 26401.041 | I17: =I16+G17 -> 260400.11
... F29: 25 | G29: =G28*((100+$K$5)/100) -> 47412.476 | I29: =I28+G29 -> 701640.24

Sheet Equipos 
E6: Panel solar
E7: Canadian solar
E8: 620 W
E9: Cantidad: 9
E20: Inversor
E21: Marca: Growatt
E22: Potencia: 5 kW
E23: Cantidad: 1
