Workbook

Sheet Desglose energía
D3: Mes | E3: Consumo antes de paneles (kWh) | G3: Precio por kWh ($/kWh) | H3: Cargo fijo ($) | J3: Cargo fijo
D4: ENERO | E4: 607 | G4: 3.55 | H4: =$J$4 -> 78 | J4: 78
D5: FEBRERO | E5: 607 | G5: 3.55 | H5: =$J$4 -> 78
D6: MARZO | E6: 504 | G6: 3.55 | H6: =$J$4 -> 78
D7: ABRIL | E7: 504 | G7: 3.55 | H7: =$J$4 -> 78
D8: MAYO | E8: 509 | G8: 3.55 | H8: =$J$4 -> 78
D9: JUNIO | E9: 509 | G9: 3.55 | H9: =$J$4 -> 78
D10: JULIO | E10: 535 | G10: 3.55 | H10: =$J$4 -> 78
D11: AGOSTO | E11: 535 | G11: 3.55 | H11: =$J$4 -> 78
D12: SEPTIEMBRE | E12: 615 | G12: 3.55 | H12: =$J$4 -> 78
D13: OCTUBRE | E13: 615 | G13: 3.55 | H13: =$J$4 -> 78
D14: NOVIEMBRE | E14: 612 | G14: 3.55 | H14: =$J$4 -> 78
D15: DICIEMBRE | E15: 612 | G15: 3.55 | H15: =$J$4 -> 78
E16: =SUM(E4:E15) -> 6764
D19: Mes | E19: Cargo fijo | F19: Energía (kWh) | G19: Total | H19: Total + IVA
D20: ENERO | E20: =H4 -> 78 | F20: =E4*G4 -> 2154.85 | G20: =E20+F20 -> 2232.85 | H20: =G20*1.16 -> 2590.106
D21: FEBRERO | E21: =H5 -> 78 | F21: =E5*G5 -> 2154.85 | G21: =E21+F21 -> 2232.85 | H21: =G21*1.16 -> 2590.106
D22: MARZO | E22: =H6 -> 78 | F22: =E6*G6 -> 1789.2 | G22: =E22+F22 -> 1867.2 | H22: =G22*1.16 -> 2165.952
D23: ABRIL | E23: =H7 -> 78 | F23: =E7*G7 -> 1789.2 | G23: =E23+F23 -> 1867.2 | H23: =G23*1.16 -> 2165.952
D24: MAYO | E24: =H8 -> 78 | F24: =E8*G8 -> 1806.95 | G24: =E24+F24 -> 1884.95 | H24: =G24*1.16 -> 2186.542
D25: JUNIO | E25: =H9 -> 78 | F25: =E9*G9 -> 1806.95 | G25: =E25+F25 -> 1884.95 | H25: =G25*1.16 -> 2186.542
D26: JULIO | E26: =H10 -> 78 | F26: =E10*G10 -> 1899.25 | G26: =E26+F26 -> 1977.25 | H26: =G26*1.16 -> 2293.61
D27: AGOSTO | E27: =H11 -> 78 | F27: =E11*G11 -> 1899.25 | G27: =E27+F27 -> 1977.25 | H27: =G27*1.16 -> 2293.61
D28: SEPTIEMBRE | E28: =H12 -> 78 | F28: =E12*G12 -> 2183.25 | G28: =E28+F28 -> 2261.25 | H28: =G28*1.16 -> 2623.05
D29: OCTUBRE | E29: =H13 -> 78 | F29: =E13*G13 -> 2183.25 | G29: =E29+F29 -> 2261.25 | H29: =G29*1.16 -> 2623.05
D30: NOVIEMBRE | E30: =H14 -> 78 | F30: =E14*G14 -> 2172.6 | G30: =E30+F30 -> 2250.6 | H30: =G30*1.16 -> 2610.696
D31: DICIEMBRE | E31: =H15 -> 78 | F31: =E15*G15 -> 2172.6 | G31: =E31+F31 -> 2250.6 | H31: =G31*1.16 -> 2610.696
H32: =SUM(H20:H31) -> 28939.912

Sheet CON FV
I3: =2.4*6*30 -> 432
H5: Generación
B6: Mes | C6: Consumo antes de paneles (kWh) | D6: Gasto antes de paneles ($) | E6: Consumo nuevo (kWh ) | F6: Gasto después de paneles solares ($) | H6: Mes | I6: Días | J6: HSP (10°) | K6: Generación | M6: EFICIENCIA SFV (%)
B7: ENERO | C7: ='Desglose energía'!E4 -> 607 | D7: ='Desglose energía'!H20 -> 2590.106 | E7: =K51 -> 0 | F7: =((C24)*1.16)+(E7*B24*1.16) -> 90.48 | H7: ENERO | I7: 31 | J7: 5.139 | K7: =ROUNDDOWN($M$19*($M$7/100)*J7*I7,0) -> 587 | M7: 75
B8: FEBRERO | C8: ='Desglose energía'!E5 -> 607 | D8: ='Desglose energía'!H21 -> 2590.106 | E8: =K52 -> 0 | F8: =((C25)*1.16)+(E8*B25*1.16) -> 90.48 | H8: FEBRERO | I8: 28 | J8: 5.877 | K8: =ROUNDDOWN($M$19*($M$7/100)*J8*I8,0) -> 607
B9: MARZO | C9: ='Desglose energía'!E6 -> 504 | D9: ='Desglose energía'!H22 -> 2165.952 | E9: =K53 -> 0 | F9: =((C26)*1.16)+(E9*B26*1.16) -> 90.48 | H9: MARZO | I9: 31 | J9: 6.372 | K9: =ROUNDDOWN($M$19*($M$7/100)*J9*I9,0) -> 728 | M9: POTENCIA REQUERIDA (KWP)
B10: ABRIL | C10: ='Desglose energía'!E7 -> 504 | D10: ='Desglose energía'!H23 -> 2165.952 | E10: =K54 -> 0 | F10: =((C27)*1.16)+(E10*B27*1.16) -> 90.48 | H10: ABRIL | I10: 30 | J10: 6.57 | K10: =ROUNDDOWN($M$19*($M$7/100)*J10*I10,0) -> 727 | M10: =ROUNDUP(C20/((M7/100)*J19*365),2) -> 4.24
B11: MAYO | C11: ='Desglose energía'!E8 -> 509 | D11: ='Desglose energía'!H24 -> 2186.542 | E11: =K55 -> 0 | F11: =((C28)*1.16)+(E11*B28*1.16) -> 90.48 | H11: MAYO | I11: 31 | J11: 6.381 | K11: =ROUNDDOWN($M$19*($M$7/100)*J11*I11,0) -> 729
B12: JUNIO | C12: ='Desglose energía'!E9 -> 509 | D12: ='Desglose energía'!H25 -> 2186.542 | E12: =K56 -> 0 | F12: =((C29)*1.16)+(E12*B29*1.16) -> 90.48 | H12: JUNIO | I12: 30 | J12: 6.039 | K12: =ROUNDDOWN($M$19*($M$7/100)*J12*I12,0) -> 668 | M12: Número de paneles
B13: JULIO | C13: ='Desglose energía'!E10 -> 535 | D13: ='Desglose energía'!H26 -> 2293.61 | E13: =K57 -> 0 | F13: =((C30)*1.16)+(E13*B30*1.16) -> 90.48 | H13: JULIO | I13: 31 | J13: 5.67 | K13: =ROUNDDOWN($M$19*($M$7/100)*J13*I13,0) -> 648 | M13: 8
B14: AGOSTO | C14: ='Desglose energía'!E11 -> 535 | D14: ='Desglose energía'!H27 -> 2293.61 | E14: =K58 -> 0 | F14: =((C31)*1.16)+(E14*B31*1.16) -> 90.48 | H14: AGOSTO | I14: 31 | J14: 5.931 | K14: =ROUNDDOWN($M$19*($M$7/100)*J14*I14,0) -> 678
B15: SEPTIEMBRE | C15: ='Desglose energía'!E12 -> 615 | D15: ='Desglose energía'!H28 -> 2623.05 | E15: =K59 -> 0 | F15: =((C32)*1.16)+(E15*B32*1.16) -> 90.48 | H15: SEPTIEMBRE | I15: 30 | J15: 5.454 | K15: =ROUNDDOWN($M$19*($M$7/100)*J15*I15,0) -> 603 | M15: Potencia del panel (Wp)
B16: OCTUBRE | C16: ='Desglose energía'!E13 -> 615 | D16: ='Desglose energía'!H29 -> 2623.05 | E16: =K60 -> 0 | F16: =((C33)*1.16)+(E16*B33*1.16) -> 90.48 | H16: OCTUBRE | I16: 31 | J16: 5.949 | K16: =ROUNDDOWN($M$19*($M$7/100)*J16*I16,0) -> 680 | M16: 615
B17: NOVIEMBRE | C17: ='Desglose energía'!E14 -> 612 | D17: ='Desglose energía'!H30 -> 2610.696 | E17: =K61 -> 0 | F17: =((C34)*1.16)+(E17*B34*1.16) -> 90.48 | H17: NOVIEMBRE | I17: 30 | J17: 5.562 | K17: =ROUNDDOWN($M$19*($M$7/100)*J17*I17,0) -> 615
B18: DICIEMBRE | C18: ='Desglose energía'!E15 -> 612 | D18: ='Desglose energía'!H31 -> 2610.696 | E18: =K62 -> 0 | F18: =((C35)*1.16)+(E18*B35*1.16) -> 90.48 | H18: DICIEMBRE | I18: 31 | J18: 5.049 | K18: =ROUNDDOWN($M$19*($M$7/100)*J18*I18,0) -> 577 | M18: POTENCIA A INSTALAR (KWP)
G19: =(C36)*1.16 -> 0 | J19: =ROUNDDOWN(AVERAGE(J7:J18),2) -> 5.83 | K19: =SUM(K7:K18) -> 7847 | M19: =(M13*M16)/1000 -> 4.92
B20: Total | C20: =SUM(C7:C18) -> 6764 | D20: =SUM(D7:D18) -> 28939.912 | E20: =SUM(E7:E18) -> 0 | F20: =SUM(F7:F18) -> 1085.76
B23: Precio por kWh ($/kWh) | C23: Cargo fijo ($)
B24: 4.062 | C24: ='Desglose energía'!H4 -> 78
B25: 4.062 | C25: ='Desglose energía'!H5 -> 78
B26: 4.062 | C26: ='Desglose energía'!H6 -> 78
B27: 4.062 | C27: ='Desglose energía'!H7 -> 78
B28: 4.062 | C28: ='Desglose energía'!H8 -> 78
B29: 4.062 | C29: ='Desglose energía'!H9 -> 78
B30: 4.062 | C30: ='Desglose energía'!H10 -> 78
B31: 4.062 | C31: ='Desglose energía'!H11 -> 78
B32: 4.062 | C32: ='Desglose energía'!H12 -> 78
B33: 4.062 | C33: ='Desglose energía'!H13 -> 78
B34: 4.062 | C34: ='Desglose energía'!H14 -> 78
B35: 4.062 | C35: ='Desglose energía'!H15 -> 78
F47: Contraprestación: No modificar*
C50: Gasto por mes | E50: Excedente | F50: ¿Aplica contraprestación?
B51: ENERO | C51: =IF(K7>=C7,0,C7-K7) -> 20 | E51: =IF(C51>0,0,K7-C7) -> 0 | F51: =IF(E51=0,$B$66,$B$67) -> NO | H51: =E64 -> 1150 | I51: =IF(H51<=0,0,H51) -> 1150 | K51: =IF(I51>=C51,0,C51-I51) -> 0
B52: FEBRERO | C52: =IF(K8>=C8,0,C8-K8) -> 0 | E52: =IF(C52>0,0,K8-C8) -> 0 | F52: =IF(E52=0,$B$66,$B$67) -> NO | H52: =H51-C51 -> 1130 | I52: =IF(H52<=0,0,H52) -> 1130 | K52: =IF(I52>=C52,0,C52-I52) -> 0
B53: MARZO | C53: =IF(K9>=C9,0,C9-K9) -> 0 | E53: =IF(C53>0,0,K9-C9) -> 224 | F53: =IF(E53=0,$B$66,$B$67) -> SI | H53: =H52-C52 -> 1130 | I53: =IF(H53<=0,0,H53) -> 1130 | K53: =IF(I53>=C53,0,C53-I53) -> 0
B54: ABRIL | C54: =IF(K10>=C10,0,C10-K10) -> 0 | E54: =IF(C54>0,0,K10-C10) -> 223 | F54: =IF(E54=0,$B$66,$B$67) -> SI | H54: =H53-C53 -> 1130 | I54: =IF(H54<=0,0,H54) -> 1130 | K54: =IF(I54>=C54,0,C54-I54) -> 0
B55: MAYO | C55: =IF(K11>=C11,0,C11-K11) -> 0 | E55: =IF(C55>0,0,K11-C11) -> 220 | F55: =IF(E55=0,$B$66,$B$67) -> SI | H55: =H54-C54 -> 1130 | I55: =IF(H55<=0,0,H55) -> 1130 | K55: =IF(I55>=C55,0,C55-I55) -> 0
B56: JUNIO | C56: =IF(K12>=C12,0,C12-K12) -> 0 | E56: =IF(C56>0,0,K12-C12) -> 159 | F56: =IF(E56=0,$B$66,$B$67) -> SI | H56: =H55-C55 -> 1130 | I56: =IF(H56<=0,0,H56) -> 1130 | K56: =IF(I56>=C56,0,C56-I56) -> 0
B57: JULIO | C57: =IF(K13>=C13,0,C13-K13) -> 0 | E57: =IF(C57>0,0,K13-C13) -> 113 | F57: =IF(E57=0,$B$66,$B$67) -> SI | H57: =H56-C56 -> 1130 | I57: =IF(H57<=0,0,H57) -> 1130 | K57: =IF(I57>=C57,0,C57-I57) -> 0
B58: AGOSTO | C58: =IF(K14>=C14,0,C14-K14) -> 0 | E58: =IF(C58>0,0,K14-C14) -> 143 | F58: =IF(E58=0,$B$66,$B$67) -> SI | H58: =H57-C57 -> 1130 | I58: =IF(H58<=0,0,H58) -> 1130 | K58: =IF(I58>=C58,0,C58-I58) -> 0
...

Sheet GRÁFICA GENERAL 
D6: Mes | E6: Consumo histórico (kWh) | F6: Energía generada por el sistema (kWh) | G6: Pago histórico ($) | H6: Pago nuevo ($) | I6: Ahorro por periodo ($)
D7: Enero | E7: ='CON FV'!C7 -> 607 | F7: ='CON FV'!K7 -> 587 | G7: ='CON FV'!D7 -> 2590.106 | H7: ='CON FV'!F7 -> 90.48 | I7: =G7-H7 -> 2499.626
D8: Febrero | E8: ='CON FV'!C8 -> 607 | F8: ='CON FV'!K8 -> 607 | G8: ='CON FV'!D8 -> 2590.106 | H8: ='CON FV'!F8 -> 90.48 | I8: =G8-H8 -> 2499.626
D9: Marzo | E9: ='CON FV'!C9 -> 504 | F9: ='CON FV'!K9 -> 728 | G9: ='CON FV'!D9 -> 2165.952 | H9: ='CON FV'!F9 -> 90.48 | I9: =G9-H9 -> 2075.472
D10: Abril | E10: ='CON FV'!C10 -> 504 | F10: ='CON FV'!K10 -> 727 | G10: ='CON FV'!D10 -> 2165.952 | H10: ='CON FV'!F10 -> 90.48 | I10: =G10-H10 -> 2075.472
D11: Mayo | E11: ='CON FV'!C11 -> 509 | F11: ='CON FV'!K11 -> 729 | G11: ='CON FV'!D11 -> 2186.542 | H11: ='CON FV'!F11 -> 90.48 | I11: =G11-H11 -> 2096.062
D12: Junio | E12: ='CON FV'!C12 -> 509 | F12: ='CON FV'!K12 -> 668 | G12: ='CON FV'!D12 -> 2186.542 | H12: ='CON FV'!F12 -> 90.48 | I12: =G12-H12 -> 2096.062
D13: Julio | E13: ='CON FV'!C13 -> 535 | F13: ='CON FV'!K13 -> 648 | G13: ='CON FV'!D13 -> 2293.61 | H13: ='CON FV'!F13 -> 90.48 | I13: =G13-H13 -> 2203.13
D14: Agosto | E14: ='CON FV'!C14 -> 535 | F14: ='CON FV'!K14 -> 678 | G14: ='CON FV'!D14 -> 2293.61 | H14: ='CON FV'!F14 -> 90.48 | I14: =G14-H14 -> 2203.13
D15: Septiembre | E15: ='CON FV'!C15 -> 615 | F15: ='CON FV'!K15 -> 603 | G15: ='CON FV'!D15 -> 2623.05 | H15: ='CON FV'!F15 -> 90.48 | I15: =G15-H15 -> 2532.57
D16: Octubre | E16: ='CON FV'!C16 -> 615 | F16: ='CON FV'!K16 -> 680 | G16: ='CON FV'!D16 -> 2623.05 | H16: ='CON FV'!F16 -> 90.48 | I16: =G16-H16 -> 2532.57
D17: Noviembre | E17: ='CON FV'!C17 -> 612 | F17: ='CON FV'!K17 -> 615 | G17: ='CON FV'!D17 -> 2610.696 | H17: ='CON FV'!F17 -> 90.48 | I17: =G17-H17 -> 2520.216
D18: Diciembre | E18: ='CON FV'!C18 -> 612 | F18: ='CON FV'!K18 -> 577 | G18: ='CON FV'!D18 -> 2610.696 | H18: ='CON FV'!F18 -> 90.48 | I18: =G18-H18 -> 2520.216
H19: Ahorro anual | I19: =SUM(I7:I18) -> 27854.152
G20: Retorno de inversión | H20: =ROUNDUP(COSTOS!H25/'GRÁFICA GENERAL '!I19,2) -> 2.44 | I20: años

Sheet COSTOS
E5: POTENCIA A INSTALAR | G5: COSTO TOTAL (MXN)
E6: ='CON FV'!M19 -> 4.92 | G6: =(E6*1000)*E9*E12 -> 67917.156
E8: COSTO POR WATT (USD /WATT) | G8: UTILIDAD PREVIA (MXN)
E9: 0.73 | G9: =G6-E15 -> 67917.156
E11: TIPO DE CAMBIO | G11: UTILIDAD FINAL (MXN)
E12: 18.91 | G12: =(G9/1.16)*0.7 -> 40984.491
E14: GASTOS EQUIPOS Y MATERIALES
G15: 76690.198
E19: Descripción | H19: Total
E20: tamaño del sistema | H20: =E6*1000 -> 4920 | I20: W
E21: Precio dólar/ watt | H21: =ROUNDUP(E9/1.16,4) -> 0.6294
E22: TC (Tipo de cambio DOF) | H22: =E12 -> 18.91
E23: Subtotal (MXN) | H23: =H20*H21*E12 -> 58557.614
E24: IVA (MXN) | H24: =H23*0.16 -> 9369.2182
E25: TOTAL (MXN) | H25: =H23+H24 -> 67926.832

Sheet Hoja1
F4: AÑO | G4: AHORRO ANUAL | I4: AHORRO ACUMULADO | K4: Inflación anual precio energía (%)
F5: 1 | G5: ='GRÁFICA GENERAL '!I19 -> 27854.152 | I5: =G5 -> 27854.152 | K5: 5
F6: 2 | G6: =G5*(1+($K$5/100)) -> 29246.86 | I6: =I5+G6 -> 57101.012
F7: 3 | G7: =G6*(1+($K$5/100)) -> 30709.203 | I7: =I6+G7 -> 87810.214
F8: 4 | G8: =G7*(1+($K$5/100)) -> 32244.663 | I8: =I7+G8 -> 120054.88
F9: 5 | G9: =G8*(1+($K$5/100)) -> 33856.896 | I9: =I8+G9 -> 153911.77
F10: 6 | G10: =G9*(1+($K$5/100)) -> 35549.741 | I10: =I9+G10 -> 189461.51
F11: 7 | G11: =G10*(1+($K$5/100)) -> 37327.228 | I11: =I10+G11 -> 226788.74
F12: 8 | G12: =G11*(1+($K$5/100)) -> 39193.589 | I12: =I11+G12 -> 265982.33
F13: 9 | G13: =G12*(1+($K$5/100)) -> 41153.269 | I13: =I12+G13 -> 307135.6
F14: 10 | G14: =G13*(1+($K$5/100)) -> 43210.932 | I14: =I13+G14 -> 350346.53
F15: 11 | G15: =G14*(1+($K$5/100)) -> 45371.479 | I15: =I14+G15 -> 395718.01
F16: 12 | G16: =G15*(1+($K$5/100)) -> 47640.052 | I16: =I15+G16 -> 443358.06
F17: 13 | G17: =G16*(1+($K$5/100)) -> 50022.055 | I17: =I16+G17 -> 493380.12
... F29: 25 | G29: =G28*(1+($K$5/100)) -> 89832.424 | I29: =I28+G29 -> 1329397.9
